Workbook

Sheet 汇总
A1: 扫描电镜指标汇总（通用规则自动管线，格式同 Wand 模板）
A2: A/D/Dh：860个全部合格导管；CWR：112个唯一相贴导管对；224个CWR1/2只作侧别追溯，不视为独立重复。跨样品41–63（共23个）合并母表；Sheet1按样品分行。
A4: 统计层级 | B4: 数值 | C4: 单位 | D4: 解释
A5: n_vessel | B5: =COUNTA(导管母表_860!C2:C861) | C5: 个导管 | D5: A/D/Dh技术观测
A6: n_pair | B6: =COUNTA(导管对_CWR_112!A2:A113) | C6: 个导管对 | D6: CWR主统计单位
A7: n_component | B7: =2*B6 | C7: 个侧别分量 | D7: CWR1/2，仅追溯；非独立
A8: n_line | B8: =COUNT(TVW线测量明细!J2:J224) | C8: 条线 | D8: 壁内技术测量
A9: n_bio | B9: 23 | C9: 个样品 | D9: Sheet1每行一个样品生物学单位
A11: 统计量 | B11: Ai (μm²) | C11: Di (μm) | D11: TVW_pair (μm) | E11: CWR_pair | F11: 层级说明
A12: n | B12: =COUNT(导管母表_860!F2:F861) | C12: =COUNT(导管母表_860!G2:G861) | D12: =COUNT(导管对_CWR_112!K2:K113) | E12: =COUNT(导管对_CWR_112!S2:S113) | F12: 导管/导管对
A13: 均值 | B13: =AVERAGE(导管母表_860!F2:F861) | C13: =AVERAGE(导管母表_860!G2:G861) | D13: =AVERAGE(导管对_CWR_112!K2:K113) | E13: =AVERAGE(导管对_CWR_112!S2:S113) | F13: CWR为pair均值
A14: SD | B14: =STDEV(导管母表_860!F2:F861) | C14: =STDEV(导管母表_860!G2:G861) | D14: =STDEV(导管对_CWR_112!K2:K113) | E14: =STDEV(导管对_CWR_112!S2:S113) | F14: 技术变异
A15: 中位数 | B15: =MEDIAN(导管母表_860!F2:F861) | C15: =MEDIAN(导管母表_860!G2:G861) | D15: =MEDIAN(导管对_CWR_112!K2:K113) | E15: =MEDIAN(导管对_CWR_112!S2:S113) | F15: 稳健位置统计
A16: Q1 | B16: =QUARTILE(导管母表_860!F2:F861,1) | C16: =QUARTILE(导管母表_860!G2:G861,1) | D16: =QUARTILE(导管对_CWR_112!K2:K113,1) | E16: =QUARTILE(导管对_CWR_112!S2:S113,1) | F16: 25%分位
A17: Q3 | B17: =QUARTILE(导管母表_860!F2:F861,3) | C17: =QUARTILE(导管母表_860!G2:G861,3) | D17: =QUARTILE(导管对_CWR_112!K2:K113,3) | E17: =QUARTILE(导管对_CWR_112!S2:S113,3) | F17: 75%分位
A18: 最小 | B18: =MIN(导管母表_860!F2:F861) | C18: =MIN(导管母表_860!G2:G861) | D18: =MIN(导管对_CWR_112!K2:K113) | E18: =MIN(导管对_CWR_112!S2:S113)
A19: 最大 | B19: =MAX(导管母表_860!F2:F861) | C19: =MAX(导管母表_860!G2:G861) | D19: =MAX(导管对_CWR_112!K2:K113) | E19: =MAX(导管对_CWR_112!S2:S113)
A20: CV (%) | B20: =B14/B13*100 | C20: =C14/C13*100 | D20: =D14/D13*100 | E20: =E14/E13*100 | F20: SD/均值×100
A22: 一致性/水力指标 | B22: 结果 | C22: 单位 | D22: 公式或说明
A23: 侧别分量算术均值 | B23: =(SUM(导管对_CWR_112!Q2:Q113)+SUM(导管对_CWR_112!R2:R113))/(2*B6) | C23: 无量纲 | D23: 应与CWR_pair均值一致；统计n仍为n_pair
A24: CWR层级一致性误差 | B24: =ABS(B23-E13) | C24: 无量纲 | D24: 应为0（浮点容差内）
A25: Dh（全库合并，仅参考） | B25: =SUMPRODUCT(导管母表_860!G2:G861^5)/SUMPRODUCT(导管母表_860!G2:G861^4) | C25: μm | D25: ΣDi⁵/ΣDi⁴；正式按样品见Sheet1
A27: CWR方案 | B27: CWR均值 | C27: 与主值差异 (%) | D27: 用途
A28: 优化主值：TVW壁内均值(3–5线) | B28: =AVERAGE(导管对_CWR_112!S2:S113) | C28: 0 | D28: 主结果
A29: 优化敏感性：TVW壁内中位数 | B29: =AVERAGE(导管对_CWR_112!V2:V113) | C29: =B29/B28*100-100 | D29: 评估壁内汇总函数
A30: 旧单线法 | B30: =AVERAGE(导管对_CWR_112!T2:T113) | C30: =B30/B28*100-100 | D30: 评估单线选择影响
A31: Dtarget版本 | B31: =AVERAGE(导管对_CWR_112!X2:X113) | C31: =B31/B28*100-100 | D31: 仅方法敏感性；非主公式

Sheet 导管母表_860
A1: 序号 | B1: 图像文件 | C1: ROI编号 | D1: 导管序号 | E1: 状态 | F1: Ai (μm²) | G1: Di=2√(Ai/π) (μm) | H1: 周长 (μm) | I1: 中心X (px) | J1: 中心Y (px) | K1: Ai敏感性下限 | L1: Ai敏感性上限 | M1: Di敏感性下限 | N1: Di敏感性上限 | O1: Pair_ID（若用于CWR） | P1: 用于A/D/Dh | Q1: 来源/质控 | R1: 样品
A2: 1 | B2: 41 (1).tif | C2: 41(1)-V01 | D2: 1 | E2: primary | F2: 1226.4414 | G2: =2*SQRT(F2/PI()) | H2: 131.3911 | I2: 437 | J2: 334 | K2: 1201.9126 | L2: 1250.9702 | M2: =2*SQRT(K2/PI()) | N2: =2*SQRT(L2/PI()) | O2: 41(1)-P01 | P2: 是 | Q2: auto_pipeline;review_png_green | R2: 样品41
A3: 2 | B3: 41 (1).tif | C3: 41(1)-V02 | D3: 2 | E3: primary | F3: 437.12193 | G3: =2*SQRT(F3/PI()) | H3: 89.633869 | I3: 599 | J3: 342 | K3: 428.37949 | L3: 445.86437 | M3: =2*SQRT(K3/PI()) | N3: =2*SQRT(L3/PI()) | O3: 41(1)-P01 | P3: 是 | Q3: auto_pipeline;review_png_green | R3: 样品41
A4: 3 | B4: 41 (1).tif | C4: 41(1)-V03 | D4: 3 | E4: primary | F4: 96.786389 | G4: =2*SQRT(F4/PI()) | H4: 37.067319 | I4: 564 | J4: 335 | K4: 94.850662 | L4: 98.722117 | M4: =2*SQRT(K4/PI()) | N4: =2*SQRT(L4/PI()) | P4: 是 | Q4: auto_pipeline;review_png_green | R4: 样品41
A5: 4 | B5: 41 (1).tif | C5: 41(1)-V04 | D5: 4 | E5: primary | F5: 68.714556 | G5: =2*SQRT(F5/PI()) | H5: 31.638936 | I5: 612 | J5: 374 | K5: 67.340265 | L5: 70.088847 | M5: =2*SQRT(K5/PI()) | N5: =2*SQRT(L5/PI()) | P5: 是 | Q5: auto_pipeline;review_png_green | R5: 样品41
A6: 5 | B6: 41 (2).tif | C6: 41(2)-V01 | D6: 1 | E6: primary | F6: 1209.8062 | G6: =2*SQRT(F6/PI()) | H6: 130.62703 | I6: 379 | J6: 436 | K6: 1185.6101 | L6: 1234.0024 | M6: =2*SQRT(K6/PI()) | N6: =2*SQRT(L6/PI()) | P6: 是 | Q6: auto_pipeline;review_png_green | R6: 样品41
A7: 6 | B7: 41 (2).tif | C7: 41(2)-V02 | D7: 2 | E7: primary | F7: 680.48204 | G7: =2*SQRT(F7/PI()) | H7: 99.730315 | I7: 520 | J7: 106 | K7: 666.8724 | L7: 694.09168 | M7: =2*SQRT(K7/PI()) | N7: =2*SQRT(L7/PI()) | P7: 是 | Q7: auto_pipeline;review_png_green | R7: 样品41
A8: 7 | B8: 41 (2).tif | C8: 41(2)-V03 | D8: 3 | E8: primary | F8: 121.88091 | G8: =2*SQRT(F8/PI()) | H8: 45.508281 | I8: 708 | J8: 263 | K8: 119.44329 | L8: 124.31853 | M8: =2*SQRT(K8/PI()) | N8: =2*SQRT(L8/PI()) | P8: 是 | Q8: auto_pipeline;review_png_green | R8: 样品41
A9: 8 | B9: 41 (3).tif | C9: 41(3)-V01 | D9: 1 | E9: primary | F9: 1465.6191 | G9: =2*SQRT(F9/PI()) | H9: 156.60099 | I9: 356 | J9: 189 | K9: 1436.3067 | L9: 1494.9315 | M9: =2*SQRT(K9/PI()) | N9: =2*SQRT(L9/PI()) | P9: 是 | Q9: auto_pipeline;review_png_green | R9: 样品41
A10: 9 | B10: 41 (3).tif | C10: 41(3)-V02 | D10: 2 | E10: primary | F10: 141.96597 | G10: =2*SQRT(F10/PI()) | H10: 75.997364 | I10: 258 | J10: 419 | K10: 139.12665 | L10: 144.80529 | M10: =2*SQRT(K10/PI()) | N10: =2*SQRT(L10/PI()) | P10: 是 | Q10: auto_pipeline;review_png_green | R10: 样品41
A11: 10 | B11: 41 (4).tif | C11: 41(4)-V01 | D11: 1 | E11: primary | F11: 1025.5671 | G11: =2*SQRT(F11/PI()) | H11: 120.51248 | I11: 440 | J11: 364 | K11: 1005.0558 | L11: 1046.0784 | M11: =2*SQRT(K11/PI()) | N11: =2*SQRT(L11/PI()) | O11: 41(4)-P01 | P11: 是 | Q11: auto_pipeline;review_png_green | R11: 样品41
A12: 11 | B12: 41 (4).tif | C12: 41(4)-V02 | D12: 2 | E12: primary | F12: 854.20605 | G12: =2*SQRT(F12/PI()) | H12: 109.76121 | I12: 644 | J12: 326 | K12: 837.12193 | L12: 871.29017 | M12: =2*SQRT(K12/PI()) | N12: =2*SQRT(L12/PI()) | O12: 41(4)-P01 | P12: 是 | Q12: auto_pipeline;review_png_green | R12: 样品41
A13: 12 | B13: 41 (4).tif | C13: 41(4)-V03 | D13: 3 | E13: primary | F13: 197.9206 | G13: =2*SQRT(F13/PI()) | H13: 53.141476 | I13: 693 | J13: 371 | K13: 193.96219 | L13: 201.87902 | M13: =2*SQRT(K13/PI()) | N13: =2*SQRT(L13/PI()) | P13: 是 | Q13: auto_pipeline;review_png_green | R13: 样品41
A14: 13 | B14: 41 (4).tif | C14: 41(4)-V04 | D14: 4 | E14: primary | F14: 117.58034 | G14: =2*SQRT(F14/PI()) | H14: 42.899586 | I14: 289 | J14: 312 | K14: 115.22873 | L14: 119.93195 | M14: =2*SQRT(K14/PI()) | N14: =2*SQRT(L14/PI()) | P14: 是 | Q14: auto_pipeline;review_png_green | R14: 样品41
A15: 14 | B15: 41 (4).tif | C15: 41(4)-V05 | D15: 5 | E15: primary | F15: 115.50095 | G15: =2*SQRT(F15/PI()) | H15: 44.53322 | I15: 724 | J15: 244 | K15: 113.19093 | L15: 117.81096 | M15: =2*SQRT(K15/PI()) | N15: =2*SQRT(L15/PI()) | P15: 是 | Q15: auto_pipeline;review_png_green | R15: 样品41
A16: 15 | B16: 41 (4).tif | C16: 41(4)-V06 | D16: 6 | E16: primary | F16: 106.00189 | G16: =2*SQRT(F16/PI()) | H16: 41.054959 | I16: 534 | J16: 246 | K16: 103.88185 | L16: 108.12193 | M16: =2*SQRT(K16/PI()) | N16: =2*SQRT(L16/PI()) | P16: 是 | Q16: auto_pipeline;review_png_green | R16: 样品41
A17: 16 | B17: 41 (5).tif | C17: 41(5)-V01 | D17: 1 | E17: primary | F17: 959.16824 | G17: =2*SQRT(F17/PI()) | H17: 116.05916 | I17: 596 | J17: 388 | K17: 939.98488 | L17: 978.35161 | M17: =2*SQRT(K17/PI()) | N17: =2*SQRT(L17/PI()) | O17: 41(5)-P01 | P17: 是 | Q17: auto_pipeline;review_png_green | R17: 样品41
A18: 17 | B18: 41 (5).tif | C18: 41(5)-V02 | D18: 2 | E18: primary | F18: 955.41115 | G18: =2*SQRT(F18/PI()) | H18: 116.4412 | I18: 425 | J18: 345 | K18: 936.30293 | L18: 974.51938 | M18: =2*SQRT(K18/PI()) | N18: =2*SQRT(L18/PI()) | O18: 41(5)-P01 | P18: 是 | Q18: auto_pipeline;review_png_green | R18: 样品41
A19: 18 | B19: 41 (5).tif | C19: 41(5)-V03 | D19: 3 | E19: primary | F19: 431.94707 | G19: =2*SQRT(F19/PI()) | H19: 82.426406 | I19: 813 | J19: 61 | K19: 423.30813 | L19: 440.58601 | M19: =2*SQRT(K19/PI()) | N19: =2*SQRT(L19/PI()) | P19: 是 | Q19: auto_pipeline;review_png_green | R19: 样品41
A20: 19 | B20: 41 (5).tif | C20: 41(5)-V04 | D20: 4 | E20: primary | F20: 127.33932 | G20: =2*SQRT(F20/PI()) | H20: 46.101308 | I20: 521 | J20: 397 | K20: 124.79253 | L20: 129.88611 | M20: =2*SQRT(K20/PI()) | N20: =2*SQRT(L20/PI()) | P20: 是 | Q20: auto_pipeline;review_png_green | R20: 样品41
A21: 20 | B21: 41 (5).tif | C21: 41(5)-V05 | D21: 5 | E21: primary | F21: 123.13327 | G21: =2*SQRT(F21/PI()) | H21: 43.132426 | I21: 736 | J21: 361 | K21: 120.6706 | L21: 125.59594 | M21: =2*SQRT(K21/PI()) | N21: =2*SQRT(L21/PI()) | P21: 是 | Q21: auto_pipeline;review_png_green | R21: 样品41
A22: 21 | B22: 41 (5).tif | C22: 41(5)-V06 | D22: 6 | E22: primary | F22: 109.82987 | G22: =2*SQRT(F22/PI()) | H22: 42.79409 | I22: 603 | J22: 99 | K22: 107.63327 | L22: 112.02647 | M22: =2*SQRT(K22/PI()) | N22: =2*SQRT(L22/PI()) | P22: 是 | Q22: auto_pipeline;review_png_green | R22: 样品41
A23: 22 | B23: 41 (6).tif | C23: 41(6)-V01 | D23: 1 | E23: primary | F23: 1294.4707 | G23: =2*SQRT(F23/PI()) | H23: 134.84751 | I23: 627 | J23: 348 | K23: 1268.5813 | L23: 1320.3601 | M23: =2*SQRT(K23/PI()) | N23: =2*SQRT(L23/PI()) | P23: 是 | Q23: auto_pipeline;review_png_green | R23: 样品41
A24: 23 | B24: 41 (6).tif | C24: 41(6)-V02 | D24: 2 | E24: primary | F24: 1075.9924 | G24: =2*SQRT(F24/PI()) | H24: 123.58686 | I24: 406 | J24: 312 | K24: 1054.4726 | L24: 1097.5123 | M24: =2*SQRT(K24/PI()) | N24: =2*SQRT(L24/PI()) | P24: 是 | Q24: auto_pipeline;review_png_green | R24: 样品41
A25: 24 | B25: 41 (6).tif | C25: 41(6)-V03 | D25: 3 | E25: primary | F25: 697.96786 | G25: =2*SQRT(F25/PI()) | H25: 100.96007 | I25: 234 | J25: 107 | K25: 684.00851 | L25: 711.92722 | M25: =2*SQRT(K25/PI()) | N25: =2*SQRT(L25/PI()) | P25: 是 | Q25: auto_pipeline;review_png_green | R25: 样品41
A26: 25 | B26: 41 (6).tif | C26: 41(6)-V04 | D26: 4 | E26: primary | F26: 136.50756 | G26: =2*SQRT(F26/PI()) | H26: 46.355997 | I26: 888 | J26: 410 | K26: 133.77741 | L26: 139.23771 | M26: =2*SQRT(K26/PI()) | N26: =2*SQRT(L26/PI()) | P26: 是 | Q26: auto_pipeline;review_png_green | R26: 样品41
A27: 26 | B27: 41 (7).tif | C27: 41(7)-V01 | D27: 1 | E27: primary | F27: 605.931 | G27: =2*SQRT(F27/PI()) | H27: 92.07527 | I27: 577 | J27: 408 | K27: 593.81238 | L27: 618.04962 | M27: =2*SQRT(K27/PI()) | N27: =2*SQRT(L27/PI()) | P27: 是 | Q27: auto_pipeline;review_png_green | R27: 样品41
A28: 27 | B28: 41 (7).tif | C28: 41(7)-V02 | D28: 2 | E28: primary | F28: 542.20227 | G28: =2*SQRT(F28/PI()) | H28: 87.389108 | I28: 444 | J28: 358 | K28: 531.35822 | L28: 553.04631 | M28: =2*SQRT(K28/PI()) | N28: =2*SQRT(L28/PI()) | O28: 41(7)-P01 | P28: 是 | Q28: auto_pipeline;review_png_green | R28: 样品41
A29: 28 | B29: 41 (7).tif | C29: 41(7)-V03 | D29: 3 | E29: primary | F29: 96.242911 | G29: =2*SQRT(F29/PI()) | H29: 40.269041 | I29: 472 | J29: 390 | K29: 94.318053 | L29: 98.167769 | M29: =2*SQRT(K29/PI()) | N29: =2*SQRT(L29/PI()) | O29: 41(7)-P01 | P29: 是 | Q29: auto_pipeline;review_png_green | R29: 样品41
A30: 29 | B30: 41 (8).tif | C30: 41(8)-V01 | D30: 1 | E30: primary | F30: 1184.4282 | G30: =2*SQRT(F30/PI()) | H30: 129.65197 | I30: 424 | J30: 293 | K30: 1160.7396 | L30: 1208.1167 | M30: =2*SQRT(K30/PI()) | N30: =2*SQRT(L30/PI()) | P30: 是 | Q30: auto_pipeline;review_png_green | R30: 样品41
A31: 30 | B31: 42 (1).tif | C31: 42(1)-V01 | D31: 1 | E31: primary | F31: 833.74291 | G31: =2*SQRT(F31/PI()) | H31: 108.27677 | I31: 609 | J31: 385 | K31: 817.06805 | L31: 850.41777 | M31: =2*SQRT(K31/PI()) | N31: =2*SQRT(L31/PI()) | O31: 42(1)-P01 | P31: 是 | Q31: auto_pipeline;review_png_green | R31: 样品42
A32: 31 | B32: 42 (1).tif | C32: 42(1)-V02 | D32: 2 | E32: primary | F32: 586.43667 | G32: =2*SQRT(F32/PI()) | H32: 90.972864 | I32: 475 | J32: 277 | K32: 574.70794 | L32: 598.16541 | M32: =2*SQRT(K32/PI()) | N32: =2*SQRT(L32/PI()) | O32: 42(1)-P01 | P32: 是 | Q32: auto_pipeline;review_png_green | R32: 样品42
A33: 32 | B33: 42 (1).tif | C33: 42(1)-V03 | D33: 3 | E33: primary | F33: 173.65312 | G33: =2*SQRT(F33/PI()) | H33: 52.144566 | I33: 389 | J33: 337 | K33: 170.18006 | L33: 177.12618 | M33: =2*SQRT(K33/PI()) | N33: =2*SQRT(L33/PI()) | P33: 是 | Q33: auto_pipeline;review_png_green | R33: 样品42
A34: 33 | B34: 42 (1).tif | C34: 42(1)-V04 | D34: 4 | E34: primary | F34: 173.60586 | G34: =2*SQRT(F34/PI()) | H34: 52.144566 | I34: 480 | J34: 418 | K34: 170.13374 | L34: 177.07798 | M34: =2*SQRT(K34/PI()) | N34: =2*SQRT(L34/PI()) | P34: 是 | Q34: auto_pipeline;review_png_green | R34: 样品42
A35: 34 | B35: 42 (1).tif | C35: 42(1)-V05 | D35: 5 | E35: primary | F35: 137.47637 | G35: =2*SQRT(F35/PI()) | H35: 44.129336 | I35: 792 | J35: 602 | K35: 134.72684 | L35: 140.2259 | M35: =2*SQRT(K35/PI()) | N35: =2*SQRT(L35/PI()) | P35: 是 | Q35: auto_pipeline;review_png_green | R35: 样品42
A36: 35 | B36: 42 (1).tif | C36: 42(1)-V06 | D36: 6 | E36: primary | F36: 124.81096 | G36: =2*SQRT(F36/PI()) | H36: 43.259771 | I36: 725 | J36: 557 | K36: 122.31474 | L36: 127.30718 | M36: =2*SQRT(K36/PI()) | N36: =2*SQRT(L36/PI()) | P36: 是 | Q36: auto_pipeline;review_png_green | R36: 样品42
A37: 36 | B37: 42 (1).tif | C37: 42(1)-V07 | D37: 7 | E37: primary | F37: 110.11342 | G37: =2*SQRT(F37/PI()) | H37: 42.433904 | I37: 57 | J37: 557 | K37: 107.91115 | L37: 112.31569 | M37: =2*SQRT(K37/PI()) | N37: =2*SQRT(L37/PI()) | P37: 是 | Q37: auto_pipeline;review_png_green | R37: 样品42
A38: 37 | B38: 42 (2).tif | C38: 42(2)-V01 | D38: 1 | E38: primary | F38: 552.6465 | G38: =2*SQRT(F38/PI()) | H38: 88.003983 | I38: 566 | J38: 331 | K38: 541.59357 | L38: 563.69943 | M38: =2*SQRT(K38/PI()) | N38: =2*SQRT(L38/PI()) | P38: 是 | Q38: auto_pipeline;review_png_green | R38: 样品42
A39: 38 | B39: 42 (2).tif | C39: 42(2)-V02 | D39: 2 | E39: primary | F39: 469.99055 | G39: =2*SQRT(F39/PI()) | H39: 81.706035 | I39: 725 | J39: 195 | K39: 460.59074 | L39: 479.39036 | M39: =2*SQRT(K39/PI()) | N39: =2*SQRT(L39/PI()) | P39: 是 | Q39: auto_pipeline;review_png_green | R39: 样品42
A40: 39 | B40: 42 (2).tif | C40: 42(2)-V03 | D40: 3 | E40: primary | F40: 334.28639 | G40: =2*SQRT(F40/PI()) | H40: 68.728103 | I40: 302 | J40: 478 | K40: 327.60066 | L40: 340.97212 | M40: =2*SQRT(K40/PI()) | N40: =2*SQRT(L40/PI()) | O40: 42(2)-P01 | P40: 是 | Q40: auto_pipeline;review_png_green | R40: 样品42
...

Sheet 候选导管审计
A1: Candidate_ID | B1: 图像文件 | C1: 中心X | D1: 中心Y | E1: 边界框 (xmin,ymin,xmax,ymax) | F1: 距最近视野边界 (px) | G1: 状态 | H1: reason_code | I1: 可可靠测量Ai/Di | J1: 主分析判定 | K1: Ai (μm²) | L1: Di (μm) | M1: 边界类别 | N1: 处理 | O1: 判定依据 | P1: 审计来源 | Q1: Pair_ID | R1: 样品
A2: 41(1)-V01 | B2: 41 (1).tif | C2: 437 | D2: 334 | E2: 349,240,526,429 | F2: 240 | G2: primary | H2: AUTO_VESSEL | I2: 是 | J2: 纳入 | K2: 1226.4414 | L2: =导管母表_860!G2 | M2: 视野内部 | N2: 纳入A/D/Dh；若有Pair_ID则纳入CWR | O2: 自动管线检出的合格导管腔。 | P2: auto_pipeline;review_png_green | Q2: 41(1)-P01 | R2: 样品41
A3: 41(1)-V02 | B3: 41 (1).tif | C3: 599 | D3: 342 | E3: 529,283,670,402 | F3: 283 | G3: primary | H3: AUTO_VESSEL | I3: 是 | J3: 纳入 | K3: 437.12193 | L3: =导管母表_860!G3 | M3: 视野内部 | N3: 纳入A/D/Dh；若有Pair_ID则纳入CWR | O3: 自动管线检出的合格导管腔。 | P3: auto_pipeline;review_png_green | Q3: 41(1)-P01 | R3: 样品41
A4: 41(1)-V03 | B4: 41 (1).tif | C4: 564 | D4: 335 | E4: 538,309,591,362 | F4: 309 | G4: primary | H4: AUTO_VESSEL | I4: 是 | J4: 纳入 | K4: 96.786389 | L4: =导管母表_860!G4 | M4: 视野内部 | N4: 纳入A/D/Dh；若有Pair_ID则纳入CWR | O4: 自动管线检出的合格导管腔。 | P4: auto_pipeline;review_png_green | R4: 样品41
A5: 41(1)-V04 | B5: 41 (1).tif | C5: 612 | D5: 374 | E5: 590,352,635,397 | F5: 352 | G5: primary | H5: AUTO_VESSEL | I5: 是 | J5: 纳入 | K5: 68.714556 | L5: =导管母表_860!G5 | M5: 视野内部 | N5: 纳入A/D/Dh；若有Pair_ID则纳入CWR | O5: 自动管线检出的合格导管腔。 | P5: auto_pipeline;review_png_green | R5: 样品41
A6: 41(2)-V01 | B6: 41 (2).tif | C6: 379 | D6: 436 | E6: 289,344,470,529 | F6: 239 | G6: primary | H6: AUTO_VESSEL | I6: 是 | J6: 纳入 | K6: 1209.8062 | L6: =导管母表_860!G6 | M6: 视野内部 | N6: 纳入A/D/Dh；若有Pair_ID则纳入CWR | O6: 自动管线检出的合格导管腔。 | P6: auto_pipeline;review_png_green | R6: 样品41
A7: 41(2)-V02 | B7: 41 (2).tif | C7: 520 | D7: 106 | E7: 445,42,596,171 | F7: 42 | G7: primary | H7: AUTO_VESSEL | I7: 是 | J7: 纳入 | K7: 680.48204 | L7: =导管母表_860!G7 | M7: 视野内部 | N7: 纳入A/D/Dh；若有Pair_ID则纳入CWR | O7: 自动管线检出的合格导管腔。 | P7: auto_pipeline;review_png_green | R7: 样品41
A8: 41(2)-V03 | B8: 41 (2).tif | C8: 708 | D8: 263 | E8: 686,223,731,304 | F8: 223 | G8: primary | H8: AUTO_VESSEL | I8: 是 | J8: 纳入 | K8: 121.88091 | L8: =导管母表_860!G8 | M8: 视野内部 | N8: 纳入A/D/Dh；若有Pair_ID则纳入CWR | O8: 自动管线检出的合格导管腔。 | P8: auto_pipeline;review_png_green | R8: 样品41
A9: 41(3)-V01 | B9: 41 (3).tif | C9: 356 | D9: 189 | E9: 247,75,466,304 | F9: 75 | G9: primary | H9: AUTO_VESSEL | I9: 是 | J9: 纳入 | K9: 1465.6191 | L9: =导管母表_860!G9 | M9: 视野内部 | N9: 纳入A/D/Dh；若有Pair_ID则纳入CWR | O9: 自动管线检出的合格导管腔。 | P9: auto_pipeline;review_png_green | R9: 样品41
A10: 41(3)-V02 | B10: 41 (3).tif | C10: 258 | D10: 419 | E10: 190,375,327,464 | F10: 190 | G10: primary | H10: AUTO_VESSEL | I10: 是 | J10: 纳入 | K10: 141.96597 | L10: =导管母表_860!G10 | M10: 视野内部 | N10: 纳入A/D/Dh；若有Pair_ID则纳入CWR | O10: 自动管线检出的合格导管腔。 | P10: auto_pipeline;review_png_green | R10: 样品41
A11: 41(4)-V01 | B11: 41 (4).tif | C11: 440 | D11: 364 | E11: 349,288,532,441 | F11: 288 | G11: primary | H11: AUTO_VESSEL | I11: 是 | J11: 纳入 | K11: 1025.5671 | L11: =导管母表_860!G11 | M11: 视野内部 | N11: 纳入A/D/Dh；若有Pair_ID则纳入CWR | O11: 自动管线检出的合格导管腔。 | P11: auto_pipeline;review_png_green | Q11: 41(4)-P01 | R11: 样品41
A12: 41(4)-V02 | B12: 41 (4).tif | C12: 644 | D12: 326 | E12: 563,255,726,398 | F12: 255 | G12: primary | H12: AUTO_VESSEL | I12: 是 | J12: 纳入 | K12: 854.20605 | L12: =导管母表_860!G12 | M12: 视野内部 | N12: 纳入A/D/Dh；若有Pair_ID则纳入CWR | O12: 自动管线检出的合格导管腔。 | P12: auto_pipeline;review_png_green | Q12: 41(4)-P01 | R12: 样品41
A13: 41(4)-V03 | B13: 41 (4).tif | C13: 693 | D13: 371 | E13: 656,334,731,409 | F13: 293 | G13: primary | H13: AUTO_VESSEL | I13: 是 | J13: 纳入 | K13: 197.9206 | L13: =导管母表_860!G13 | M13: 视野内部 | N13: 纳入A/D/Dh；若有Pair_ID则纳入CWR | O13: 自动管线检出的合格导管腔。 | P13: auto_pipeline;review_png_green | R13: 样品41
A14: 41(4)-V04 | B14: 41 (4).tif | C14: 289 | D14: 312 | E14: 255,287,324,338 | F14: 255 | G14: primary | H14: AUTO_VESSEL | I14: 是 | J14: 纳入 | K14: 117.58034 | L14: =导管母表_860!G14 | M14: 视野内部 | N14: 纳入A/D/Dh；若有Pair_ID则纳入CWR | O14: 自动管线检出的合格导管腔。 | P14: auto_pipeline;review_png_green | R14: 样品41
A15: 41(4)-V05 | B15: 41 (4).tif | C15: 724 | D15: 244 | E15: 683,225,766,264 | F15: 225 | G15: primary | H15: AUTO_VESSEL | I15: 是 | J15: 纳入 | K15: 115.50095 | L15: =导管母表_860!G15 | M15: 视野内部 | N15: 纳入A/D/Dh；若有Pair_ID则纳入CWR | O15: 自动管线检出的合格导管腔。 | P15: auto_pipeline;review_png_green | R15: 样品41
A16: 41(4)-V06 | B16: 41 (4).tif | C16: 534 | D16: 246 | E16: 500,224,569,269 | F16: 224 | G16: primary | H16: AUTO_VESSEL | I16: 是 | J16: 纳入 | K16: 106.00189 | L16: =导管母表_860!G16 | M16: 视野内部 | N16: 纳入A/D/Dh；若有Pair_ID则纳入CWR | O16: 自动管线检出的合格导管腔。 | P16: auto_pipeline;review_png_green | R16: 样品41
A17: 41(5)-V01 | B17: 41 (5).tif | C17: 596 | D17: 388 | E17: 511,312,682,465 | F17: 303 | G17: primary | H17: AUTO_VESSEL | I17: 是 | J17: 纳入 | K17: 959.16824 | L17: =导管母表_860!G17 | M17: 视野内部 | N17: 纳入A/D/Dh；若有Pair_ID则纳入CWR | O17: 自动管线检出的合格导管腔。 | P17: auto_pipeline;review_png_green | Q17: 41(5)-P01 | R17: 样品41
A18: 41(5)-V02 | B18: 41 (5).tif | C18: 425 | D18: 345 | E18: 342,267,509,424 | F18: 267 | G18: primary | H18: AUTO_VESSEL | I18: 是 | J18: 纳入 | K18: 955.41115 | L18: =导管母表_860!G18 | M18: 视野内部 | N18: 纳入A/D/Dh；若有Pair_ID则纳入CWR | O18: 自动管线检出的合格导管腔。 | P18: auto_pipeline;review_png_green | Q18: 41(5)-P01 | R18: 样品41
A19: 41(5)-V03 | B19: 41 (5).tif | C19: 813 | D19: 61 | E19: 747,12,880,111 | F19: 12 | G19: primary | H19: AUTO_VESSEL | I19: 是 | J19: 纳入 | K19: 431.94707 | L19: =导管母表_860!G19 | M19: 近边缘（<25 px） | N19: 纳入A/D/Dh；若有Pair_ID则纳入CWR | O19: 自动管线检出的合格导管腔。 | P19: auto_pipeline;review_png_green | R19: 样品41
A20: 41(5)-V04 | B20: 41 (5).tif | C20: 521 | D20: 397 | E20: 492,362,551,433 | F20: 335 | G20: primary | H20: AUTO_VESSEL | I20: 是 | J20: 纳入 | K20: 127.33932 | L20: =导管母表_860!G20 | M20: 视野内部 | N20: 纳入A/D/Dh；若有Pair_ID则纳入CWR | O20: 自动管线检出的合格导管腔。 | P20: auto_pipeline;review_png_green | R20: 样品41
A21: 41(5)-V05 | B21: 41 (5).tif | C21: 736 | D21: 361 | E21: 709,328,764,395 | F21: 260 | G21: primary | H21: AUTO_VESSEL | I21: 是 | J21: 纳入 | K21: 123.13327 | L21: =导管母表_860!G21 | M21: 视野内部 | N21: 纳入A/D/Dh；若有Pair_ID则纳入CWR | O21: 自动管线检出的合格导管腔。 | P21: auto_pipeline;review_png_green | R21: 样品41
A22: 41(5)-V06 | B22: 41 (5).tif | C22: 603 | D22: 99 | E22: 565,79,642,120 | F22: 79 | G22: primary | H22: AUTO_VESSEL | I22: 是 | J22: 纳入 | K22: 109.82987 | L22: =导管母表_860!G22 | M22: 视野内部 | N22: 纳入A/D/Dh；若有Pair_ID则纳入CWR | O22: 自动管线检出的合格导管腔。 | P22: auto_pipeline;review_png_green | R22: 样品41
A23: 41(6)-V01 | B23: 41 (6).tif | C23: 627 | D23: 348 | E23: 529,259,726,438 | F23: 259 | G23: primary | H23: AUTO_VESSEL | I23: 是 | J23: 纳入 | K23: 1294.4707 | L23: =导管母表_860!G23 | M23: 视野内部 | N23: 纳入A/D/Dh；若有Pair_ID则纳入CWR | O23: 自动管线检出的合格导管腔。 | P23: auto_pipeline;review_png_green | R23: 样品41
A24: 41(6)-V02 | B24: 41 (6).tif | C24: 406 | D24: 312 | E24: 319,227,494,398 | F24: 227 | G24: primary | H24: AUTO_VESSEL | I24: 是 | J24: 纳入 | K24: 1075.9924 | L24: =导管母表_860!G24 | M24: 视野内部 | N24: 纳入A/D/Dh；若有Pair_ID则纳入CWR | O24: 自动管线检出的合格导管腔。 | P24: auto_pipeline;review_png_green | R24: 样品41
A25: 41(6)-V03 | B25: 41 (6).tif | C25: 234 | D25: 107 | E25: 163,37,306,178 | F25: 37 | G25: primary | H25: AUTO_VESSEL | I25: 是 | J25: 纳入 | K25: 697.96786 | L25: =导管母表_860!G25 | M25: 视野内部 | N25: 纳入A/D/Dh；若有Pair_ID则纳入CWR | O25: 自动管线检出的合格导管腔。 | P25: auto_pipeline;review_png_green | R25: 样品41
A26: 41(6)-V04 | B26: 41 (6).tif | C26: 888 | D26: 410 | E26: 862,372,915,449 | F26: 109 | G26: primary | H26: AUTO_VESSEL | I26: 是 | J26: 纳入 | K26: 136.50756 | L26: =导管母表_860!G26 | M26: 视野内部 | N26: 纳入A/D/Dh；若有Pair_ID则纳入CWR | O26: 自动管线检出的合格导管腔。 | P26: auto_pipeline;review_png_green | R26: 样品41
A27: 41(7)-V01 | B27: 41 (7).tif | C27: 577 | D27: 408 | E27: 510,347,645,470 | F27: 298 | G27: primary | H27: AUTO_VESSEL | I27: 是 | J27: 纳入 | K27: 605.931 | L27: =导管母表_860!G27 | M27: 视野内部 | N27: 纳入A/D/Dh；若有Pair_ID则纳入CWR | O27: 自动管线检出的合格导管腔。 | P27: auto_pipeline;review_png_green | R27: 样品41
A28: 41(7)-V02 | B28: 41 (7).tif | C28: 444 | D28: 358 | E28: 386,295,503,422 | F28: 295 | G28: primary | H28: AUTO_VESSEL | I28: 是 | J28: 纳入 | K28: 542.20227 | L28: =导管母表_860!G28 | M28: 视野内部 | N28: 纳入A/D/Dh；若有Pair_ID则纳入CWR | O28: 自动管线检出的合格导管腔。 | P28: auto_pipeline;review_png_green | Q28: 41(7)-P01 | R28: 样品41
A29: 41(7)-V03 | B29: 41 (7).tif | C29: 472 | D29: 390 | E29: 445,360,500,421 | F29: 347 | G29: primary | H29: AUTO_VESSEL | I29: 是 | J29: 纳入 | K29: 96.242911 | L29: =导管母表_860!G29 | M29: 视野内部 | N29: 纳入A/D/Dh；若有Pair_ID则纳入CWR | O29: 自动管线检出的合格导管腔。 | P29: auto_pipeline;review_png_green | Q29: 41(7)-P01 | R29: 样品41
A30: 41(8)-V01 | B30: 41 (8).tif | C30: 424 | D30: 293 | E30: 330,207,519,380 | F30: 207 | G30: primary | H30: AUTO_VESSEL | I30: 是 | J30: 纳入 | K30: 1184.4282 | L30: =导管母表_860!G30 | M30: 视野内部 | N30: 纳入A/D/Dh；若有Pair_ID则纳入CWR | O30: 自动管线检出的合格导管腔。 | P30: auto_pipeline;review_png_green | R30: 样品41
A31: 42(1)-V01 | B31: 42 (1).tif | C31: 609 | D31: 385 | E31: 534,310,685,461 | F31: 307 | G31: primary | H31: AUTO_VESSEL | I31: 是 | J31: 纳入 | K31: 833.74291 | L31: =导管母表_860!G31 | M31: 视野内部 | N31: 纳入A/D/Dh；若有Pair_ID则纳入CWR | O31: 自动管线检出的合格导管腔。 | P31: auto_pipeline;review_png_green | Q31: 42(1)-P01 | R31: 样品42
A32: 42(1)-V02 | B32: 42 (1).tif | C32: 475 | D32: 277 | E32: 407,219,544,336 | F32: 219 | G32: primary | H32: AUTO_VESSEL | I32: 是 | J32: 纳入 | K32: 586.43667 | L32: =导管母表_860!G32 | M32: 视野内部 | N32: 纳入A/D/Dh；若有Pair_ID则纳入CWR | O32: 自动管线检出的合格导管腔。 | P32: auto_pipeline;review_png_green | Q32: 42(1)-P01 | R32: 样品42
A33: 42(1)-V03 | B33: 42 (1).tif | C33: 389 | D33: 337 | E33: 357,296,422,379 | F33: 296 | G33: primary | H33: AUTO_VESSEL | I33: 是 | J33: 纳入 | K33: 173.65312 | L33: =导管母表_860!G33 | M33: 视野内部 | N33: 纳入A/D/Dh；若有Pair_ID则纳入CWR | O33: 自动管线检出的合格导管腔。 | P33: auto_pipeline;review_png_green | R33: 样品42
A34: 42(1)-V04 | B34: 42 (1).tif | C34: 480 | D34: 418 | E34: 440,385,521,452 | F34: 316 | G34: primary | H34: AUTO_VESSEL | I34: 是 | J34: 纳入 | K34: 173.60586 | L34: =导管母表_860!G34 | M34: 视野内部 | N34: 纳入A/D/Dh；若有Pair_ID则纳入CWR | O34: 自动管线检出的合格导管腔。 | P34: auto_pipeline;review_png_green | R34: 样品42
A35: 42(1)-V05 | B35: 42 (1).tif | C35: 792 | D35: 602 | E35: 764,569,821,636 | F35: 132 | G35: primary | H35: AUTO_VESSEL | I35: 是 | J35: 纳入 | K35: 137.47637 | L35: =导管母表_860!G35 | M35: 视野内部 | N35: 纳入A/D/Dh；若有Pair_ID则纳入CWR | O35: 自动管线检出的合格导管腔。 | P35: auto_pipeline;review_png_green | R35: 样品42
A36: 42(1)-V06 | B36: 42 (1).tif | C36: 725 | D36: 557 | E36: 693,529,758,586 | F36: 182 | G36: primary | H36: AUTO_VESSEL | I36: 是 | J36: 纳入 | K36: 124.81096 | L36: =导管母表_860!G36 | M36: 视野内部 | N36: 纳入A/D/Dh；若有Pair_ID则纳入CWR | O36: 自动管线检出的合格导管腔。 | P36: auto_pipeline;review_png_green | R36: 样品42
A37: 42(1)-V07 | B37: 42 (1).tif | C37: 57 | D37: 557 | E37: 20,537,95,578 | F37: 20 | G37: primary | H37: AUTO_VESSEL | I37: 是 | J37: 纳入 | K37: 110.11342 | L37: =导管母表_860!G37 | M37: 近边缘（<25 px） | N37: 纳入A/D/Dh；若有Pair_ID则纳入CWR | O37: 自动管线检出的合格导管腔。 | P37: auto_pipeline;review_png_green | R37: 样品42
A38: 42(2)-V01 | B38: 42 (2).tif | C38: 566 | D38: 331 | E38: 506,269,627,394 | F38: 269 | G38: primary | H38: AUTO_VESSEL | I38: 是 | J38: 纳入 | K38: 552.6465 | L38: =导管母表_860!G38 | M38: 视野内部 | N38: 纳入A/D/Dh；若有Pair_ID则纳入CWR | O38: 自动管线检出的合格导管腔。 | P38: auto_pipeline;review_png_green | R38: 样品42
A39: 42(2)-V02 | B39: 42 (2).tif | C39: 725 | D39: 195 | E39: 663,144,788,247 | F39: 144 | G39: primary | H39: AUTO_VESSEL | I39: 是 | J39: 纳入 | K39: 469.99055 | L39: =导管母表_860!G39 | M39: 视野内部 | N39: 纳入A/D/Dh；若有Pair_ID则纳入CWR | O39: 自动管线检出的合格导管腔。 | P39: auto_pipeline;review_png_green | R39: 样品42
A40: 42(2)-V03 | B40: 42 (2).tif | C40: 302 | D40: 478 | E40: 254,431,351,526 | F40: 242 | G40: primary | H40: AUTO_VESSEL | I40: 是 | J40: 纳入 | K40: 334.28639 | L40: =导管母表_860!G40 | M40: 视野内部 | N40: 纳入A/D/Dh；若有Pair_ID则纳入CWR | O40: 自动管线检出的合格导管腔。 | P40: auto_pipeline;review_png_green | Q40: 42(2)-P01 | R40: 样品42
...

Sheet 视野统计
A1: 图像 | B1: primary导管 | C1: borderline候选（含未测） | D1: excluded候选 | E1: edge_truncated筛查候选 | F1: 相贴导管对 | G1: TVW线数 | H1: 像素尺寸 (μm/px) | I1: 组织高 (px) | J1: 视野面积 (mm²) | K1: 说明 | L1: 样品
A2: 41 (1).tif | B2: =COUNTIF(导管母表_860!B:B,A2) | C2: =COUNTIFS(候选导管审计!B:B,A2,候选导管审计!G:G,"borderline") | D2: =COUNTIFS(候选导管审计!B:B,A2,候选导管审计!G:G,"excluded") | E2: =COUNTIFS(候选导管审计!B:B,A2,候选导管审计!G:G,"edge_truncated") | F2: =COUNTIF(导管对_CWR_112!B:B,A2) | G2: =COUNTIF(TVW线测量明细!B:B,A2) | H2: 0.2173913 | I2: 201 | J2: =1024*I2*H2^2/1000000 | K2: 同一样品的技术视野；不是独立生物学重复 | L2: 样品41
A3: 41 (2).tif | B3: =COUNTIF(导管母表_860!B:B,A3) | C3: =COUNTIFS(候选导管审计!B:B,A3,候选导管审计!G:G,"borderline") | D3: =COUNTIFS(候选导管审计!B:B,A3,候选导管审计!G:G,"excluded") | E3: =COUNTIFS(候选导管审计!B:B,A3,候选导管审计!G:G,"edge_truncated") | F3: =COUNTIF(导管对_CWR_112!B:B,A3) | G3: =COUNTIF(TVW线测量明细!B:B,A3) | H3: 0.2173913 | I3: 691 | J3: =1024*I3*H3^2/1000000 | K3: 同一样品的技术视野；不是独立生物学重复 | L3: 样品41
A4: 41 (3).tif | B4: =COUNTIF(导管母表_860!B:B,A4) | C4: =COUNTIFS(候选导管审计!B:B,A4,候选导管审计!G:G,"borderline") | D4: =COUNTIFS(候选导管审计!B:B,A4,候选导管审计!G:G,"excluded") | E4: =COUNTIFS(候选导管审计!B:B,A4,候选导管审计!G:G,"edge_truncated") | F4: =COUNTIF(导管对_CWR_112!B:B,A4) | G4: =COUNTIF(TVW线测量明细!B:B,A4) | H4: 0.2173913 | I4: 691 | J4: =1024*I4*H4^2/1000000 | K4: 同一样品的技术视野；不是独立生物学重复 | L4: 样品41
A5: 41 (4).tif | B5: =COUNTIF(导管母表_860!B:B,A5) | C5: =COUNTIFS(候选导管审计!B:B,A5,候选导管审计!G:G,"borderline") | D5: =COUNTIFS(候选导管审计!B:B,A5,候选导管审计!G:G,"excluded") | E5: =COUNTIFS(候选导管审计!B:B,A5,候选导管审计!G:G,"edge_truncated") | F5: =COUNTIF(导管对_CWR_112!B:B,A5) | G5: =COUNTIF(TVW线测量明细!B:B,A5) | H5: 0.2173913 | I5: 197 | J5: =1024*I5*H5^2/1000000 | K5: 同一样品的技术视野；不是独立生物学重复 | L5: 样品41
A6: 41 (5).tif | B6: =COUNTIF(导管母表_860!B:B,A6) | C6: =COUNTIFS(候选导管审计!B:B,A6,候选导管审计!G:G,"borderline") | D6: =COUNTIFS(候选导管审计!B:B,A6,候选导管审计!G:G,"excluded") | E6: =COUNTIFS(候选导管审计!B:B,A6,候选导管审计!G:G,"edge_truncated") | F6: =COUNTIF(导管对_CWR_112!B:B,A6) | G6: =COUNTIF(TVW线测量明细!B:B,A6) | H6: 0.2173913 | I6: 209 | J6: =1024*I6*H6^2/1000000 | K6: 同一样品的技术视野；不是独立生物学重复 | L6: 样品41
A7: 41 (6).tif | B7: =COUNTIF(导管母表_860!B:B,A7) | C7: =COUNTIFS(候选导管审计!B:B,A7,候选导管审计!G:G,"borderline") | D7: =COUNTIFS(候选导管审计!B:B,A7,候选导管审计!G:G,"excluded") | E7: =COUNTIFS(候选导管审计!B:B,A7,候选导管审计!G:G,"edge_truncated") | F7: =COUNTIF(导管对_CWR_112!B:B,A7) | G7: =COUNTIF(TVW线测量明细!B:B,A7) | H7: 0.2173913 | I7: 691 | J7: =1024*I7*H7^2/1000000 | K7: 同一样品的技术视野；不是独立生物学重复 | L7: 样品41
A8: 41 (7).tif | B8: =COUNTIF(导管母表_860!B:B,A8) | C8: =COUNTIFS(候选导管审计!B:B,A8,候选导管审计!G:G,"borderline") | D8: =COUNTIFS(候选导管审计!B:B,A8,候选导管审计!G:G,"excluded") | E8: =COUNTIFS(候选导管审计!B:B,A8,候选导管审计!G:G,"edge_truncated") | F8: =COUNTIF(导管对_CWR_112!B:B,A8) | G8: =COUNTIF(TVW线测量明细!B:B,A8) | H8: 0.2173913 | I8: 188 | J8: =1024*I8*H8^2/1000000 | K8: 同一样品的技术视野；不是独立生物学重复 | L8: 样品41
A9: 41 (8).tif | B9: =COUNTIF(导管母表_860!B:B,A9) | C9: =COUNTIFS(候选导管审计!B:B,A9,候选导管审计!G:G,"borderline") | D9: =COUNTIFS(候选导管审计!B:B,A9,候选导管审计!G:G,"excluded") | E9: =COUNTIFS(候选导管审计!B:B,A9,候选导管审计!G:G,"edge_truncated") | F9: =COUNTIF(导管对_CWR_112!B:B,A9) | G9: =COUNTIF(TVW线测量明细!B:B,A9) | H9: 0.2173913 | I9: 691 | J9: =1024*I9*H9^2/1000000 | K9: 同一样品的技术视野；不是独立生物学重复 | L9: 样品41
A10: 42 (1).tif | B10: =COUNTIF(导管母表_860!B:B,A10) | C10: =COUNTIFS(候选导管审计!B:B,A10,候选导管审计!G:G,"borderline") | D10: =COUNTIFS(候选导管审计!B:B,A10,候选导管审计!G:G,"excluded") | E10: =COUNTIFS(候选导管审计!B:B,A10,候选导管审计!G:G,"edge_truncated") | F10: =COUNTIF(导管对_CWR_112!B:B,A10) | G10: =COUNTIF(TVW线测量明细!B:B,A10) | H10: 0.2173913 | I10: 246 | J10: =1024*I10*H10^2/1000000 | K10: 同一样品的技术视野；不是独立生物学重复 | L10: 样品42
A11: 42 (2).tif | B11: =COUNTIF(导管母表_860!B:B,A11) | C11: =COUNTIFS(候选导管审计!B:B,A11,候选导管审计!G:G,"borderline") | D11: =COUNTIFS(候选导管审计!B:B,A11,候选导管审计!G:G,"excluded") | E11: =COUNTIFS(候选导管审计!B:B,A11,候选导管审计!G:G,"edge_truncated") | F11: =COUNTIF(导管对_CWR_112!B:B,A11) | G11: =COUNTIF(TVW线测量明细!B:B,A11) | H11: 0.2173913 | I11: 166 | J11: =1024*I11*H11^2/1000000 | K11: 同一样品的技术视野；不是独立生物学重复 | L11: 样品42
A12: 42 (3).tif | B12: =COUNTIF(导管母表_860!B:B,A12) | C12: =COUNTIFS(候选导管审计!B:B,A12,候选导管审计!G:G,"borderline") | D12: =COUNTIFS(候选导管审计!B:B,A12,候选导管审计!G:G,"excluded") | E12: =COUNTIFS(候选导管审计!B:B,A12,候选导管审计!G:G,"edge_truncated") | F12: =COUNTIF(导管对_CWR_112!B:B,A12) | G12: =COUNTIF(TVW线测量明细!B:B,A12) | H12: 0.2173913 | I12: 222 | J12: =1024*I12*H12^2/1000000 | K12: 同一样品的技术视野；不是独立生物学重复 | L12: 样品42
A13: 42 (4).tif | B13: =COUNTIF(导管母表_860!B:B,A13) | C13: =COUNTIFS(候选导管审计!B:B,A13,候选导管审计!G:G,"borderline") | D13: =COUNTIFS(候选导管审计!B:B,A13,候选导管审计!G:G,"excluded") | E13: =COUNTIFS(候选导管审计!B:B,A13,候选导管审计!G:G,"edge_truncated") | F13: =COUNTIF(导管对_CWR_112!B:B,A13) | G13: =COUNTIF(TVW线测量明细!B:B,A13) | H13: 0.2173913 | I13: 691 | J13: =1024*I13*H13^2/1000000 | K13: 同一样品的技术视野；不是独立生物学重复 | L13: 样品42
... A185: 63 (8).tif | B185: =COUNTIF(导管母表_860!B:B,A185) | C185: =COUNTIFS(候选导管审计!B:B,A185,候选导管审计!G:G,"borderline") | D185: =COUNTIFS(候选导管审计!B:B,A185,候选导管审计!G:G,"excluded") | E185: =COUNTIFS(候选导管审计!B:B,A185,候选导管审计!G:G,"edge_truncated") | F185: =COUNTIF(导管对_CWR_112!B:B,A185) | G185: =COUNTIF(TVW线测量明细!B:B,A185) | H185: 0.2173913 | I185: 691 | J185: =1024*I185*H185^2/1000000 | K185: 同一样品的技术视野；不是独立生物学重复 | L185: 样品63
A186: 合计 | B186: =SUM(B2:B185) | C186: =SUM(C2:C185) | D186: =SUM(D2:D185) | E186: =SUM(E2:E185) | F186: =SUM(F2:F185) | G186: =SUM(G2:G185) | J186: =SUM(J2:J185) | K186: 184个视野在样品层面按样品合并后写入Sheet1

Sheet 导管对_CWR_112
A1: Pair_ID | B1: 图像文件 | C1: 导管1 ROI | D1: Ai1 (μm²) | E1: Di1 (μm) | F1: 导管2 ROI | G1: Ai2 (μm²) | H1: Di2 (μm) | I1: TVW线表范围 | J1: n_line | K1: TVW均值 (μm，主值) | L1: TVW中位数 (μm) | M1: TVW线内SD (μm) | N1: TVW线内CV (%) | O1: 旧单线TVW (μm) | P1: TVW变化 (%) | Q1: CWR1=(TVW/Di1)² | R1: CWR2=(TVW/Di2)² | S1: CWR_pair（主值） | T1: 旧单线CWR_pair | U1: CWR变化 (%) | V1: 线中位数法CWR_pair（敏感性） | W1: Dtarget（仅敏感性） | X1: Dtarget法CWR（仅敏感性） | Y1: 壁级QC | Z1: 对应关系质控 | AA1: 样品
A2: 41(1)-P01 | B2: 41 (1).tif | C2: 41(1)-V01 | D2: =导管母表_860!F2 | E2: =导管母表_860!G2 | F2: 41(1)-V02 | G2: =导管母表_860!F3 | H2: =导管母表_860!G3 | I2: J2:J4 | J2: =COUNT(TVW线测量明细!J2:J4) | K2: =AVERAGE(TVW线测量明细!J2:J4) | L2: =MEDIAN(TVW线测量明细!J2:J4) | M2: =IF(J2>1,STDEV(TVW线测量明细!J2:J4),0) | N2: =IF(K2=0,"",M2/K2*100) | O2: 2.4786422 | P2: =IF(O2=0,"",(K2/O2-1)*100) | Q2: =(K2/E2)^2 | R2: =(K2/H2)^2 | S2: =AVERAGE(Q2,R2) | T2: =AVERAGE((O2/E2)^2,(O2/H2)^2) | U2: =IF(T2=0,"",(S2/T2-1)*100) | V2: =AVERAGE((L2/E2)^2,(L2/H2)^2) | W2: =IF(ABS(E2-汇总!B25)<=ABS(H2-汇总!B25),E2,H2) | X2: =(K2/W2)^2 | Y2: =IF(N2>10,"HIGH_TVW_CV",IF(J2<3,"SHORT_INTERFACE","PASS")) | Z2: Di1、TVW均值、Di2均来自本Pair_ID；TVW=3–5法线平均 | AA2: 样品41
A3: 41(4)-P01 | B3: 41 (4).tif | C3: 41(4)-V01 | D3: =导管母表_860!F11 | E3: =导管母表_860!G11 | F3: 41(4)-V02 | G3: =导管母表_860!F12 | H3: =导管母表_860!G12 | I3: J5:J5 | J3: =COUNT(TVW线测量明细!J5:J5) | K3: =AVERAGE(TVW线测量明细!J5:J5) | L3: =MEDIAN(TVW线测量明细!J5:J5) | M3: =IF(J3>1,STDEV(TVW线测量明细!J5:J5),0) | N3: =IF(K3=0,"",M3/K3*100) | O3: 7.7196873 | P3: =IF(O3=0,"",(K3/O3-1)*100) | Q3: =(K3/E3)^2 | R3: =(K3/H3)^2 | S3: =AVERAGE(Q3,R3) | T3: =AVERAGE((O3/E3)^2,(O3/H3)^2) | U3: =IF(T3=0,"",(S3/T3-1)*100) | V3: =AVERAGE((L3/E3)^2,(L3/H3)^2) | W3: =IF(ABS(E3-汇总!B25)<=ABS(H3-汇总!B25),E3,H3) | X3: =(K3/W3)^2 | Y3: =IF(N3>10,"HIGH_TVW_CV",IF(J3<3,"SHORT_INTERFACE","PASS")) | Z3: Di1、TVW均值、Di2均来自本Pair_ID；TVW=3–5法线平均 | AA3: 样品41
A4: 41(5)-P01 | B4: 41 (5).tif | C4: 41(5)-V01 | D4: =导管母表_860!F17 | E4: =导管母表_860!G17 | F4: 41(5)-V02 | G4: =导管母表_860!F18 | H4: =导管母表_860!G18 | I4: J6:J7 | J4: =COUNT(TVW线测量明细!J6:J7) | K4: =AVERAGE(TVW线测量明细!J6:J7) | L4: =MEDIAN(TVW线测量明细!J6:J7) | M4: =IF(J4>1,STDEV(TVW线测量明细!J6:J7),0) | N4: =IF(K4=0,"",M4/K4*100) | O4: 1.5217391 | P4: =IF(O4=0,"",(K4/O4-1)*100) | Q4: =(K4/E4)^2 | R4: =(K4/H4)^2 | S4: =AVERAGE(Q4,R4) | T4: =AVERAGE((O4/E4)^2,(O4/H4)^2) | U4: =IF(T4=0,"",(S4/T4-1)*100) | V4: =AVERAGE((L4/E4)^2,(L4/H4)^2) | W4: =IF(ABS(E4-汇总!B25)<=ABS(H4-汇总!B25),E4,H4) | X4: =(K4/W4)^2 | Y4: =IF(N4>10,"HIGH_TVW_CV",IF(J4<3,"SHORT_INTERFACE","PASS")) | Z4: Di1、TVW均值、Di2均来自本Pair_ID；TVW=3–5法线平均 | AA4: 样品41
A5: 41(7)-P01 | B5: 41 (7).tif | C5: 41(7)-V02 | D5: =导管母表_860!F28 | E5: =导管母表_860!G28 | F5: 41(7)-V03 | G5: =导管母表_860!F29 | H5: =导管母表_860!G29 | I5: J8:J8 | J5: =COUNT(TVW线测量明细!J8:J8) | K5: =AVERAGE(TVW线测量明细!J8:J8) | L5: =MEDIAN(TVW线测量明细!J8:J8) | M5: =IF(J5>1,STDEV(TVW线测量明细!J8:J8),0) | N5: =IF(K5=0,"",M5/K5*100) | O5: 0 | P5: =IF(O5=0,"",(K5/O5-1)*100) | Q5: =(K5/E5)^2 | R5: =(K5/H5)^2 | S5: =AVERAGE(Q5,R5) | T5: =AVERAGE((O5/E5)^2,(O5/H5)^2) | U5: =IF(T5=0,"",(S5/T5-1)*100) | V5: =AVERAGE((L5/E5)^2,(L5/H5)^2) | W5: =IF(ABS(E5-汇总!B25)<=ABS(H5-汇总!B25),E5,H5) | X5: =(K5/W5)^2 | Y5: =IF(N5>10,"HIGH_TVW_CV",IF(J5<3,"SHORT_INTERFACE","PASS")) | Z5: Di1、TVW均值、Di2均来自本Pair_ID；TVW=3–5法线平均 | AA5: 样品41
A6: 42(1)-P01 | B6: 42 (1).tif | C6: 42(1)-V01 | D6: =导管母表_860!F31 | E6: =导管母表_860!G31 | F6: 42(1)-V02 | G6: =导管母表_860!F32 | H6: =导管母表_860!G32 | I6: J9:J11 | J6: =COUNT(TVW线测量明细!J9:J11) | K6: =AVERAGE(TVW线测量明细!J9:J11) | L6: =MEDIAN(TVW线测量明细!J9:J11) | M6: =IF(J6>1,STDEV(TVW线测量明细!J9:J11),0) | N6: =IF(K6=0,"",M6/K6*100) | O6: 6.9190567 | P6: =IF(O6=0,"",(K6/O6-1)*100) | Q6: =(K6/E6)^2 | R6: =(K6/H6)^2 | S6: =AVERAGE(Q6,R6) | T6: =AVERAGE((O6/E6)^2,(O6/H6)^2) | U6: =IF(T6=0,"",(S6/T6-1)*100) | V6: =AVERAGE((L6/E6)^2,(L6/H6)^2) | W6: =IF(ABS(E6-汇总!B25)<=ABS(H6-汇总!B25),E6,H6) | X6: =(K6/W6)^2 | Y6: =IF(N6>10,"HIGH_TVW_CV",IF(J6<3,"SHORT_INTERFACE","PASS")) | Z6: Di1、TVW均值、Di2均来自本Pair_ID；TVW=3–5法线平均 | AA6: 样品42
A7: 42(2)-P01 | B7: 42 (2).tif | C7: 42(2)-V03 | D7: =导管母表_860!F40 | E7: =导管母表_860!G40 | F7: 42(2)-V04 | G7: =导管母表_860!F41 | H7: =导管母表_860!G41 | I7: J12:J13 | J7: =COUNT(TVW线测量明细!J12:J13) | K7: =AVERAGE(TVW线测量明细!J12:J13) | L7: =MEDIAN(TVW线测量明细!J12:J13) | M7: =IF(J7>1,STDEV(TVW线测量明细!J12:J13),0) | N7: =IF(K7=0,"",M7/K7*100) | O7: 4.7677635 | P7: =IF(O7=0,"",(K7/O7-1)*100) | Q7: =(K7/E7)^2 | R7: =(K7/H7)^2 | S7: =AVERAGE(Q7,R7) | T7: =AVERAGE((O7/E7)^2,(O7/H7)^2) | U7: =IF(T7=0,"",(S7/T7-1)*100) | V7: =AVERAGE((L7/E7)^2,(L7/H7)^2) | W7: =IF(ABS(E7-汇总!B25)<=ABS(H7-汇总!B25),E7,H7) | X7: =(K7/W7)^2 | Y7: =IF(N7>10,"HIGH_TVW_CV",IF(J7<3,"SHORT_INTERFACE","PASS")) | Z7: Di1、TVW均值、Di2均来自本Pair_ID；TVW=3–5法线平均 | AA7: 样品42
A8: 42(3)-P01 | B8: 42 (3).tif | C8: 42(3)-V01 | D8: =导管母表_860!F43 | E8: =导管母表_860!G43 | F8: 42(3)-V02 | G8: =导管母表_860!F44 | H8: =导管母表_860!G44 | I8: J14:J15 | J8: =COUNT(TVW线测量明细!J14:J15) | K8: =AVERAGE(TVW线测量明细!J14:J15) | L8: =MEDIAN(TVW线测量明细!J14:J15) | M8: =IF(J8>1,STDEV(TVW线测量明细!J14:J15),0) | N8: =IF(K8=0,"",M8/K8*100) | O8: 5.130619 | P8: =IF(O8=0,"",(K8/O8-1)*100) | Q8: =(K8/E8)^2 | R8: =(K8/H8)^2 | S8: =AVERAGE(Q8,R8) | T8: =AVERAGE((O8/E8)^2,(O8/H8)^2) | U8: =IF(T8=0,"",(S8/T8-1)*100) | V8: =AVERAGE((L8/E8)^2,(L8/H8)^2) | W8: =IF(ABS(E8-汇总!B25)<=ABS(H8-汇总!B25),E8,H8) | X8: =(K8/W8)^2 | Y8: =IF(N8>10,"HIGH_TVW_CV",IF(J8<3,"SHORT_INTERFACE","PASS")) | Z8: Di1、TVW均值、Di2均来自本Pair_ID；TVW=3–5法线平均 | AA8: 样品42
A9: 42(5)-P01 | B9: 42 (5).tif | C9: 42(5)-V01 | D9: =导管母表_860!F49 | E9: =导管母表_860!G49 | F9: 42(5)-V03 | G9: =导管母表_860!F51 | H9: =导管母表_860!G51 | I9: J16:J17 | J9: =COUNT(TVW线测量明细!J16:J17) | K9: =AVERAGE(TVW线测量明细!J16:J17) | L9: =MEDIAN(TVW线测量明细!J16:J17) | M9: =IF(J9>1,STDEV(TVW线测量明细!J16:J17),0) | N9: =IF(K9=0,"",M9/K9*100) | O9: 8.1688236 | P9: =IF(O9=0,"",(K9/O9-1)*100) | Q9: =(K9/E9)^2 | R9: =(K9/H9)^2 | S9: =AVERAGE(Q9,R9) | T9: =AVERAGE((O9/E9)^2,(O9/H9)^2) | U9: =IF(T9=0,"",(S9/T9-1)*100) | V9: =AVERAGE((L9/E9)^2,(L9/H9)^2) | W9: =IF(ABS(E9-汇总!B25)<=ABS(H9-汇总!B25),E9,H9) | X9: =(K9/W9)^2 | Y9: =IF(N9>10,"HIGH_TVW_CV",IF(J9<3,"SHORT_INTERFACE","PASS")) | Z9: Di1、TVW均值、Di2均来自本Pair_ID；TVW=3–5法线平均 | AA9: 样品42
A10: 42(6)-P01 | B10: 42 (6).tif | C10: 42(6)-V01 | D10: =导管母表_860!F53 | E10: =导管母表_860!G53 | F10: 42(6)-V03 | G10: =导管母表_860!F55 | H10: =导管母表_860!G55 | I10: J18:J19 | J10: =COUNT(TVW线测量明细!J18:J19) | K10: =AVERAGE(TVW线测量明细!J18:J19) | L10: =MEDIAN(TVW线测量明细!J18:J19) | M10: =IF(J10>1,STDEV(TVW线测量明细!J18:J19),0) | N10: =IF(K10=0,"",M10/K10*100) | O10: 5.1673323 | P10: =IF(O10=0,"",(K10/O10-1)*100) | Q10: =(K10/E10)^2 | R10: =(K10/H10)^2 | S10: =AVERAGE(Q10,R10) | T10: =AVERAGE((O10/E10)^2,(O10/H10)^2) | U10: =IF(T10=0,"",(S10/T10-1)*100) | V10: =AVERAGE((L10/E10)^2,(L10/H10)^2) | W10: =IF(ABS(E10-汇总!B25)<=ABS(H10-汇总!B25),E10,H10) | X10: =(K10/W10)^2 | Y10: =IF(N10>10,"HIGH_TVW_CV",IF(J10<3,"SHORT_INTERFACE","PASS")) | Z10: Di1、TVW均值、Di2均来自本Pair_ID；TVW=3–5法线平均 | AA10: 样品42
A11: 42(7)-P01 | B11: 42 (7).tif | C11: 42(7)-V01 | D11: =导管母表_860!F58 | E11: =导管母表_860!G58 | F11: 42(7)-V02 | G11: =导管母表_860!F59 | H11: =导管母表_860!G59 | I11: J20:J20 | J11: =COUNT(TVW线测量明细!J20:J20) | K11: =AVERAGE(TVW线测量明细!J20:J20) | L11: =MEDIAN(TVW线测量明细!J20:J20) | M11: =IF(J11>1,STDEV(TVW线测量明细!J20:J20),0) | N11: =IF(K11=0,"",M11/K11*100) | O11: 4.4816365 | P11: =IF(O11=0,"",(K11/O11-1)*100) | Q11: =(K11/E11)^2 | R11: =(K11/H11)^2 | S11: =AVERAGE(Q11,R11) | T11: =AVERAGE((O11/E11)^2,(O11/H11)^2) | U11: =IF(T11=0,"",(S11/T11-1)*100) | V11: =AVERAGE((L11/E11)^2,(L11/H11)^2) | W11: =IF(ABS(E11-汇总!B25)<=ABS(H11-汇总!B25),E11,H11) | X11: =(K11/W11)^2 | Y11: =IF(N11>10,"HIGH_TVW_CV",IF(J11<3,"SHORT_INTERFACE","PASS")) | Z11: Di1、TVW均值、Di2均来自本Pair_ID；TVW=3–5法线平均 | AA11: 样品42
A12: 42(8)-P01 | B12: 42 (8).tif | C12: 42(8)-V02 | D12: =导管母表_860!F62 | E12: =导管母表_860!G62 | F12: 42(8)-V03 | G12: =导管母表_860!F63 | H12: =导管母表_860!G63 | I12: J21:J21 | J12: =COUNT(TVW线测量明细!J21:J21) | K12: =AVERAGE(TVW线测量明细!J21:J21) | L12: =MEDIAN(TVW线测量明细!J21:J21) | M12: =IF(J12>1,STDEV(TVW线测量明细!J21:J21),0) | N12: =IF(K12=0,"",M12/K12*100) | O12: 2.6446794 | P12: =IF(O12=0,"",(K12/O12-1)*100) | Q12: =(K12/E12)^2 | R12: =(K12/H12)^2 | S12: =AVERAGE(Q12,R12) | T12: =AVERAGE((O12/E12)^2,(O12/H12)^2) | U12: =IF(T12=0,"",(S12/T12-1)*100) | V12: =AVERAGE((L12/E12)^2,(L12/H12)^2) | W12: =IF(ABS(E12-汇总!B25)<=ABS(H12-汇总!B25),E12,H12) | X12: =(K12/W12)^2 | Y12: =IF(N12>10,"HIGH_TVW_CV",IF(J12<3,"SHORT_INTERFACE","PASS")) | Z12: Di1、TVW均值、Di2均来自本Pair_ID；TVW=3–5法线平均 | AA12: 样品42
A13: 43(3)-P01 | B13: 43 (3).tif | C13: 43(3)-V01 | D13: =导管母表_860!F70 | E13: =导管母表_860!G70 | F13: 43(3)-V02 | G13: =导管母表_860!F71 | H13: =导管母表_860!G71 | I13: J22:J22 | J13: =COUNT(TVW线测量明细!J22:J22) | K13: =AVERAGE(TVW线测量明细!J22:J22) | L13: =MEDIAN(TVW线测量明细!J22:J22) | M13: =IF(J13>1,STDEV(TVW线测量明细!J22:J22),0) | N13: =IF(K13=0,"",M13/K13*100) | O13: 5.3779639 | P13: =IF(O13=0,"",(K13/O13-1)*100) | Q13: =(K13/E13)^2 | R13: =(K13/H13)^2 | S13: =AVERAGE(Q13,R13) | T13: =AVERAGE((O13/E13)^2,(O13/H13)^2) | U13: =IF(T13=0,"",(S13/T13-1)*100) | V13: =AVERAGE((L13/E13)^2,(L13/H13)^2) | W13: =IF(ABS(E13-汇总!B25)<=ABS(H13-汇总!B25),E13,H13) | X13: =(K13/W13)^2 | Y13: =IF(N13>10,"HIGH_TVW_CV",IF(J13<3,"SHORT_INTERFACE","PASS")) | Z13: Di1、TVW均值、Di2均来自本Pair_ID；TVW=3–5法线平均 | AA13: 样品43
A14: 43(4)-P01 | B14: 43 (4).tif | C14: 43(4)-V02 | D14: =导管母表_860!F75 | E14: =导管母表_860!G75 | F14: 43(4)-V03 | G14: =导管母表_860!F76 | H14: =导管母表_860!G76 | I14: J23:J24 | J14: =COUNT(TVW线测量明细!J23:J24) | K14: =AVERAGE(TVW线测量明细!J23:J24) | L14: =MEDIAN(TVW线测量明细!J23:J24) | M14: =IF(J14>1,STDEV(TVW线测量明细!J23:J24),0) | N14: =IF(K14=0,"",M14/K14*100) | O14: 3.8888139 | P14: =IF(O14=0,"",(K14/O14-1)*100) | Q14: =(K14/E14)^2 | R14: =(K14/H14)^2 | S14: =AVERAGE(Q14,R14) | T14: =AVERAGE((O14/E14)^2,(O14/H14)^2) | U14: =IF(T14=0,"",(S14/T14-1)*100) | V14: =AVERAGE((L14/E14)^2,(L14/H14)^2) | W14: =IF(ABS(E14-汇总!B25)<=ABS(H14-汇总!B25),E14,H14) | X14: =(K14/W14)^2 | Y14: =IF(N14>10,"HIGH_TVW_CV",IF(J14<3,"SHORT_INTERFACE","PASS")) | Z14: Di1、TVW均值、Di2均来自本Pair_ID；TVW=3–5法线平均 | AA14: 样品43
A15: 43(5)-P01 | B15: 43 (5).tif | C15: 43(5)-V01 | D15: =导管母表_860!F78 | E15: =导管母表_860!G78 | F15: 43(5)-V02 | G15: =导管母表_860!F79 | H15: =导管母表_860!G79 | I15: J25:J25 | J15: =COUNT(TVW线测量明细!J25:J25) | K15: =AVERAGE(TVW线测量明细!J25:J25) | L15: =MEDIAN(TVW线测量明细!J25:J25) | M15: =IF(J15>1,STDEV(TVW线测量明细!J25:J25),0) | N15: =IF(K15=0,"",M15/K15*100) | O15: 3.7965759 | P15: =IF(O15=0,"",(K15/O15-1)*100) | Q15: =(K15/E15)^2 | R15: =(K15/H15)^2 | S15: =AVERAGE(Q15,R15) | T15: =AVERAGE((O15/E15)^2,(O15/H15)^2) | U15: =IF(T15=0,"",(S15/T15-1)*100) | V15: =AVERAGE((L15/E15)^2,(L15/H15)^2) | W15: =IF(ABS(E15-汇总!B25)<=ABS(H15-汇总!B25),E15,H15) | X15: =(K15/W15)^2 | Y15: =IF(N15>10,"HIGH_TVW_CV",IF(J15<3,"SHORT_INTERFACE","PASS")) | Z15: Di1、TVW均值、Di2均来自本Pair_ID；TVW=3–5法线平均 | AA15: 样品43
A16: 44(1)-P01 | B16: 44 (1).tif | C16: 44(1)-V03 | D16: =导管母表_860!F90 | E16: =导管母表_860!G90 | F16: 44(1)-V06 | G16: =导管母表_860!F93 | H16: =导管母表_860!G93 | I16: J26:J26 | J16: =COUNT(TVW线测量明细!J26:J26) | K16: =AVERAGE(TVW线测量明细!J26:J26) | L16: =MEDIAN(TVW线测量明细!J26:J26) | M16: =IF(J16>1,STDEV(TVW线测量明细!J26:J26),0) | N16: =IF(K16=0,"",M16/K16*100) | O16: 1.0869565 | P16: =IF(O16=0,"",(K16/O16-1)*100) | Q16: =(K16/E16)^2 | R16: =(K16/H16)^2 | S16: =AVERAGE(Q16,R16) | T16: =AVERAGE((O16/E16)^2,(O16/H16)^2) | U16: =IF(T16=0,"",(S16/T16-1)*100) | V16: =AVERAGE((L16/E16)^2,(L16/H16)^2) | W16: =IF(ABS(E16-汇总!B25)<=ABS(H16-汇总!B25),E16,H16) | X16: =(K16/W16)^2 | Y16: =IF(N16>10,"HIGH_TVW_CV",IF(J16<3,"SHORT_INTERFACE","PASS")) | Z16: Di1、TVW均值、Di2均来自本Pair_ID；TVW=3–5法线平均 | AA16: 样品44
A17: 44(2)-P01 | B17: 44 (2).tif | C17: 44(2)-V01 | D17: =导管母表_860!F94 | E17: =导管母表_860!G94 | F17: 44(2)-V02 | G17: =导管母表_860!F95 | H17: =导管母表_860!G95 | I17: J27:J28 | J17: =COUNT(TVW线测量明细!J27:J28) | K17: =AVERAGE(TVW线测量明细!J27:J28) | L17: =MEDIAN(TVW线测量明细!J27:J28) | M17: =IF(J17>1,STDEV(TVW线测量明细!J27:J28),0) | N17: =IF(K17=0,"",M17/K17*100) | O17: 4.5703904 | P17: =IF(O17=0,"",(K17/O17-1)*100) | Q17: =(K17/E17)^2 | R17: =(K17/H17)^2 | S17: =AVERAGE(Q17,R17) | T17: =AVERAGE((O17/E17)^2,(O17/H17)^2) | U17: =IF(T17=0,"",(S17/T17-1)*100) | V17: =AVERAGE((L17/E17)^2,(L17/H17)^2) | W17: =IF(ABS(E17-汇总!B25)<=ABS(H17-汇总!B25),E17,H17) | X17: =(K17/W17)^2 | Y17: =IF(N17>10,"HIGH_TVW_CV",IF(J17<3,"SHORT_INTERFACE","PASS")) | Z17: Di1、TVW均值、Di2均来自本Pair_ID；TVW=3–5法线平均 | AA17: 样品44
A18: 44(3)-P01 | B18: 44 (3).tif | C18: 44(3)-V02 | D18: =导管母表_860!F98 | E18: =导管母表_860!G98 | F18: 44(3)-V03 | G18: =导管母表_860!F99 | H18: =导管母表_860!G99 | I18: J29:J29 | J18: =COUNT(TVW线测量明细!J29:J29) | K18: =AVERAGE(TVW线测量明细!J29:J29) | L18: =MEDIAN(TVW线测量明细!J29:J29) | M18: =IF(J18>1,STDEV(TVW线测量明细!J29:J29),0) | N18: =IF(K18=0,"",M18/K18*100) | O18: 6.53983 | P18: =IF(O18=0,"",(K18/O18-1)*100) | Q18: =(K18/E18)^2 | R18: =(K18/H18)^2 | S18: =AVERAGE(Q18,R18) | T18: =AVERAGE((O18/E18)^2,(O18/H18)^2) | U18: =IF(T18=0,"",(S18/T18-1)*100) | V18: =AVERAGE((L18/E18)^2,(L18/H18)^2) | W18: =IF(ABS(E18-汇总!B25)<=ABS(H18-汇总!B25),E18,H18) | X18: =(K18/W18)^2 | Y18: =IF(N18>10,"HIGH_TVW_CV",IF(J18<3,"SHORT_INTERFACE","PASS")) | Z18: Di1、TVW均值、Di2均来自本Pair_ID；TVW=3–5法线平均 | AA18: 样品44
A19: 44(4)-P01 | B19: 44 (4).tif | C19: 44(4)-V02 | D19: =导管母表_860!F101 | E19: =导管母表_860!G101 | F19: 44(4)-V05 | G19: =导管母表_860!F104 | H19: =导管母表_860!G104 | I19: J30:J30 | J19: =COUNT(TVW线测量明细!J30:J30) | K19: =AVERAGE(TVW线测量明细!J30:J30) | L19: =MEDIAN(TVW线测量明细!J30:J30) | M19: =IF(J19>1,STDEV(TVW线测量明细!J30:J30),0) | N19: =IF(K19=0,"",M19/K19*100) | O19: 0.78381549 | P19: =IF(O19=0,"",(K19/O19-1)*100) | Q19: =(K19/E19)^2 | R19: =(K19/H19)^2 | S19: =AVERAGE(Q19,R19) | T19: =AVERAGE((O19/E19)^2,(O19/H19)^2) | U19: =IF(T19=0,"",(S19/T19-1)*100) | V19: =AVERAGE((L19/E19)^2,(L19/H19)^2) | W19: =IF(ABS(E19-汇总!B25)<=ABS(H19-汇总!B25),E19,H19) | X19: =(K19/W19)^2 | Y19: =IF(N19>10,"HIGH_TVW_CV",IF(J19<3,"SHORT_INTERFACE","PASS")) | Z19: Di1、TVW均值、Di2均来自本Pair_ID；TVW=3–5法线平均 | AA19: 样品44
A20: 44(5)-P01 | B20: 44 (5).tif | C20: 44(5)-V02 | D20: =导管母表_860!F106 | E20: =导管母表_860!G106 | F20: 44(5)-V06 | G20: =导管母表_860!F110 | H20: =导管母表_860!G110 | I20: J31:J31 | J20: =COUNT(TVW线测量明细!J31:J31) | K20: =AVERAGE(TVW线测量明细!J31:J31) | L20: =MEDIAN(TVW线测量明细!J31:J31) | M20: =IF(J20>1,STDEV(TVW线测量明细!J31:J31),0) | N20: =IF(K20=0,"",M20/K20*100) | O20: 1.3223397 | P20: =IF(O20=0,"",(K20/O20-1)*100) | Q20: =(K20/E20)^2 | R20: =(K20/H20)^2 | S20: =AVERAGE(Q20,R20) | T20: =AVERAGE((O20/E20)^2,(O20/H20)^2) | U20: =IF(T20=0,"",(S20/T20-1)*100) | V20: =AVERAGE((L20/E20)^2,(L20/H20)^2) | W20: =IF(ABS(E20-汇总!B25)<=ABS(H20-汇总!B25),E20,H20) | X20: =(K20/W20)^2 | Y20: =IF(N20>10,"HIGH_TVW_CV",IF(J20<3,"SHORT_INTERFACE","PASS")) | Z20: Di1、TVW均值、Di2均来自本Pair_ID；TVW=3–5法线平均 | AA20: 样品44
A21: 44(6)-P01 | B21: 44 (6).tif | C21: 44(6)-V02 | D21: =导管母表_860!F112 | E21: =导管母表_860!G112 | F21: 44(6)-V03 | G21: =导管母表_860!F113 | H21: =导管母表_860!G113 | I21: J32:J34 | J21: =COUNT(TVW线测量明细!J32:J34) | K21: =AVERAGE(TVW线测量明细!J32:J34) | L21: =MEDIAN(TVW线测量明细!J32:J34) | M21: =IF(J21>1,STDEV(TVW线测量明细!J32:J34),0) | N21: =IF(K21=0,"",M21/K21*100) | O21: 6.2175433 | P21: =IF(O21=0,"",(K21/O21-1)*100) | Q21: =(K21/E21)^2 | R21: =(K21/H21)^2 | S21: =AVERAGE(Q21,R21) | T21: =AVERAGE((O21/E21)^2,(O21/H21)^2) | U21: =IF(T21=0,"",(S21/T21-1)*100) | V21: =AVERAGE((L21/E21)^2,(L21/H21)^2) | W21: =IF(ABS(E21-汇总!B25)<=ABS(H21-汇总!B25),E21,H21) | X21: =(K21/W21)^2 | Y21: =IF(N21>10,"HIGH_TVW_CV",IF(J21<3,"SHORT_INTERFACE","PASS")) | Z21: Di1、TVW均值、Di2均来自本Pair_ID；TVW=3–5法线平均 | AA21: 样品44
A22: 44(7)-P01 | B22: 44 (7).tif | C22: 44(7)-V01 | D22: =导管母表_860!F114 | E22: =导管母表_860!G114 | F22: 44(7)-V02 | G22: =导管母表_860!F115 | H22: =导管母表_860!G115 | I22: J35:J36 | J22: =COUNT(TVW线测量明细!J35:J36) | K22: =AVERAGE(TVW线测量明细!J35:J36) | L22: =MEDIAN(TVW线测量明细!J35:J36) | M22: =IF(J22>1,STDEV(TVW线测量明细!J35:J36),0) | N22: =IF(K22=0,"",M22/K22*100) | O22: 8.7741026 | P22: =IF(O22=0,"",(K22/O22-1)*100) | Q22: =(K22/E22)^2 | R22: =(K22/H22)^2 | S22: =AVERAGE(Q22,R22) | T22: =AVERAGE((O22/E22)^2,(O22/H22)^2) | U22: =IF(T22=0,"",(S22/T22-1)*100) | V22: =AVERAGE((L22/E22)^2,(L22/H22)^2) | W22: =IF(ABS(E22-汇总!B25)<=ABS(H22-汇总!B25),E22,H22) | X22: =(K22/W22)^2 | Y22: =IF(N22>10,"HIGH_TVW_CV",IF(J22<3,"SHORT_INTERFACE","PASS")) | Z22: Di1、TVW均值、Di2均来自本Pair_ID；TVW=3–5法线平均 | AA22: 样品44
A23: 44(8)-P01 | B23: 44 (8).tif | C23: 44(8)-V02 | D23: =导管母表_860!F117 | E23: =导管母表_860!G117 | F23: 44(8)-V04 | G23: =导管母表_860!F119 | H23: =导管母表_860!G119 | I23: J37:J37 | J23: =COUNT(TVW线测量明细!J37:J37) | K23: =AVERAGE(TVW线测量明细!J37:J37) | L23: =MEDIAN(TVW线测量明细!J37:J37) | M23: =IF(J23>1,STDEV(TVW线测量明细!J37:J37),0) | N23: =IF(K23=0,"",M23/K23*100) | O23: 7.8532139 | P23: =IF(O23=0,"",(K23/O23-1)*100) | Q23: =(K23/E23)^2 | R23: =(K23/H23)^2 | S23: =AVERAGE(Q23,R23) | T23: =AVERAGE((O23/E23)^2,(O23/H23)^2) | U23: =IF(T23=0,"",(S23/T23-1)*100) | V23: =AVERAGE((L23/E23)^2,(L23/H23)^2) | W23: =IF(ABS(E23-汇总!B25)<=ABS(H23-汇总!B25),E23,H23) | X23: =(K23/W23)^2 | Y23: =IF(N23>10,"HIGH_TVW_CV",IF(J23<3,"SHORT_INTERFACE","PASS")) | Z23: Di1、TVW均值、Di2均来自本Pair_ID；TVW=3–5法线平均 | AA23: 样品44
A24: 45(1)-P01 | B24: 45 (1).tif | C24: 45(1)-V02 | D24: =导管母表_860!F123 | E24: =导管母表_860!G123 | F24: 45(1)-V05 | G24: =导管母表_860!F126 | H24: =导管母表_860!G126 | I24: J38:J38 | J24: =COUNT(TVW线测量明细!J38:J38) | K24: =AVERAGE(TVW线测量明细!J38:J38) | L24: =MEDIAN(TVW线测量明细!J38:J38) | M24: =IF(J24>1,STDEV(TVW线测量明细!J38:J38),0) | N24: =IF(K24=0,"",M24/K24*100) | O24: 4.9620488 | P24: =IF(O24=0,"",(K24/O24-1)*100) | Q24: =(K24/E24)^2 | R24: =(K24/H24)^2 | S24: =AVERAGE(Q24,R24) | T24: =AVERAGE((O24/E24)^2,(O24/H24)^2) | U24: =IF(T24=0,"",(S24/T24-1)*100) | V24: =AVERAGE((L24/E24)^2,(L24/H24)^2) | W24: =IF(ABS(E24-汇总!B25)<=ABS(H24-汇总!B25),E24,H24) | X24: =(K24/W24)^2 | Y24: =IF(N24>10,"HIGH_TVW_CV",IF(J24<3,"SHORT_INTERFACE","PASS")) | Z24: Di1、TVW均值、Di2均来自本Pair_ID；TVW=3–5法线平均 | AA24: 样品45
A25: 45(1)-P02 | B25: 45 (1).tif | C25: 45(1)-V03 | D25: =导管母表_860!F124 | E25: =导管母表_860!G124 | F25: 45(1)-V08 | G25: =导管母表_860!F129 | H25: =导管母表_860!G129 | I25: J39:J39 | J25: =COUNT(TVW线测量明细!J39:J39) | K25: =AVERAGE(TVW线测量明细!J39:J39) | L25: =MEDIAN(TVW线测量明细!J39:J39) | M25: =IF(J25>1,STDEV(TVW线测量明细!J39:J39),0) | N25: =IF(K25=0,"",M25/K25*100) | O25: 0 | P25: =IF(O25=0,"",(K25/O25-1)*100) | Q25: =(K25/E25)^2 | R25: =(K25/H25)^2 | S25: =AVERAGE(Q25,R25) | T25: =AVERAGE((O25/E25)^2,(O25/H25)^2) | U25: =IF(T25=0,"",(S25/T25-1)*100) | V25: =AVERAGE((L25/E25)^2,(L25/H25)^2) | W25: =IF(ABS(E25-汇总!B25)<=ABS(H25-汇总!B25),E25,H25) | X25: =(K25/W25)^2 | Y25: =IF(N25>10,"HIGH_TVW_CV",IF(J25<3,"SHORT_INTERFACE","PASS")) | Z25: Di1、TVW均值、Di2均来自本Pair_ID；TVW=3–5法线平均 | AA25: 样品45
A26: 45(2)-P01 | B26: 45 (2).tif | C26: 45(2)-V03 | D26: =导管母表_860!F132 | E26: =导管母表_860!G132 | F26: 45(2)-V07 | G26: =导管母表_860!F136 | H26: =导管母表_860!G136 | I26: J40:J40 | J26: =COUNT(TVW线测量明细!J40:J40) | K26: =AVERAGE(TVW线测量明细!J40:J40) | L26: =MEDIAN(TVW线测量明细!J40:J40) | M26: =IF(J26>1,STDEV(TVW线测量明细!J40:J40),0) | N26: =IF(K26=0,"",M26/K26*100) | O26: 0.43478261 | P26: =IF(O26=0,"",(K26/O26-1)*100) | Q26: =(K26/E26)^2 | R26: =(K26/H26)^2 | S26: =AVERAGE(Q26,R26) | T26: =AVERAGE((O26/E26)^2,(O26/H26)^2) | U26: =IF(T26=0,"",(S26/T26-1)*100) | V26: =AVERAGE((L26/E26)^2,(L26/H26)^2) | W26: =IF(ABS(E26-汇总!B25)<=ABS(H26-汇总!B25),E26,H26) | X26: =(K26/W26)^2 | Y26: =IF(N26>10,"HIGH_TVW_CV",IF(J26<3,"SHORT_INTERFACE","PASS")) | Z26: Di1、TVW均值、Di2均来自本Pair_ID；TVW=3–5法线平均 | AA26: 样品45
A27: 45(4)-P01 | B27: 45 (4).tif | C27: 45(4)-V02 | D27: =导管母表_860!F142 | E27: =导管母表_860!G142 | F27: 45(4)-V06 | G27: =导管母表_860!F146 | H27: =导管母表_860!G146 | I27: J41:J42 | J27: =COUNT(TVW线测量明细!J41:J42) | K27: =AVERAGE(TVW线测量明细!J41:J42) | L27: =MEDIAN(TVW线测量明细!J41:J42) | M27: =IF(J27>1,STDEV(TVW线测量明细!J41:J42),0) | N27: =IF(K27=0,"",M27/K27*100) | O27: 2.2696318 | P27: =IF(O27=0,"",(K27/O27-1)*100) | Q27: =(K27/E27)^2 | R27: =(K27/H27)^2 | S27: =AVERAGE(Q27,R27) | T27: =AVERAGE((O27/E27)^2,(O27/H27)^2) | U27: =IF(T27=0,"",(S27/T27-1)*100) | V27: =AVERAGE((L27/E27)^2,(L27/H27)^2) | W27: =IF(ABS(E27-汇总!B25)<=ABS(H27-汇总!B25),E27,H27) | X27: =(K27/W27)^2 | Y27: =IF(N27>10,"HIGH_TVW_CV",IF(J27<3,"SHORT_INTERFACE","PASS")) | Z27: Di1、TVW均值、Di2均来自本Pair_ID；TVW=3–5法线平均 | AA27: 样品45
A28: 45(5)-P01 | B28: 45 (5).tif | C28: 45(5)-V01 | D28: =导管母表_860!F149 | E28: =导管母表_860!G149 | F28: 45(5)-V02 | G28: =导管母表_860!F150 | H28: =导管母表_860!G150 | I28: J43:J43 | J28: =COUNT(TVW线测量明细!J43:J43) | K28: =AVERAGE(TVW线测量明细!J43:J43) | L28: =MEDIAN(TVW线测量明细!J43:J43) | M28: =IF(J28>1,STDEV(TVW线测量明细!J43:J43),0) | N28: =IF(K28=0,"",M28/K28*100) | O28: 0 | P28: =IF(O28=0,"",(K28/O28-1)*100) | Q28: =(K28/E28)^2 | R28: =(K28/H28)^2 | S28: =AVERAGE(Q28,R28) | T28: =AVERAGE((O28/E28)^2,(O28/H28)^2) | U28: =IF(T28=0,"",(S28/T28-1)*100) | V28: =AVERAGE((L28/E28)^2,(L28/H28)^2) | W28: =IF(ABS(E28-汇总!B25)<=ABS(H28-汇总!B25),E28,H28) | X28: =(K28/W28)^2 | Y28: =IF(N28>10,"HIGH_TVW_CV",IF(J28<3,"SHORT_INTERFACE","PASS")) | Z28: Di1、TVW均值、Di2均来自本Pair_ID；TVW=3–5法线平均 | AA28: 样品45
A29: 45(6)-P01 | B29: 45 (6).tif | C29: 45(6)-V01 | D29: =导管母表_860!F153 | E29: =导管母表_860!G153 | F29: 45(6)-V02 | G29: =导管母表_860!F154 | H29: =导管母表_860!G154 | I29: J44:J45 | J29: =COUNT(TVW线测量明细!J44:J45) | K29: =AVERAGE(TVW线测量明细!J44:J45) | L29: =MEDIAN(TVW线测量明细!J44:J45) | M29: =IF(J29>1,STDEV(TVW线测量明细!J44:J45),0) | N29: =IF(K29=0,"",M29/K29*100) | O29: 5.4347826 | P29: =IF(O29=0,"",(K29/O29-1)*100) | Q29: =(K29/E29)^2 | R29: =(K29/H29)^2 | S29: =AVERAGE(Q29,R29) | T29: =AVERAGE((O29/E29)^2,(O29/H29)^2) | U29: =IF(T29=0,"",(S29/T29-1)*100) | V29: =AVERAGE((L29/E29)^2,(L29/H29)^2) | W29: =IF(ABS(E29-汇总!B25)<=ABS(H29-汇总!B25),E29,H29) | X29: =(K29/W29)^2 | Y29: =IF(N29>10,"HIGH_TVW_CV",IF(J29<3,"SHORT_INTERFACE","PASS")) | Z29: Di1、TVW均值、Di2均来自本Pair_ID；TVW=3–5法线平均 | AA29: 样品45
A30: 45(7)-P01 | B30: 45 (7).tif | C30: 45(7)-V01 | D30: =导管母表_860!F155 | E30: =导管母表_860!G155 | F30: 45(7)-V02 | G30: =导管母表_860!F156 | H30: =导管母表_860!G156 | I30: J46:J47 | J30: =COUNT(TVW线测量明细!J46:J47) | K30: =AVERAGE(TVW线测量明细!J46:J47) | L30: =MEDIAN(TVW线测量明细!J46:J47) | M30: =IF(J30>1,STDEV(TVW线测量明细!J46:J47),0) | N30: =IF(K30=0,"",M30/K30*100) | O30: 7.6365948 | P30: =IF(O30=0,"",(K30/O30-1)*100) | Q30: =(K30/E30)^2 | R30: =(K30/H30)^2 | S30: =AVERAGE(Q30,R30) | T30: =AVERAGE((O30/E30)^2,(O30/H30)^2) | U30: =IF(T30=0,"",(S30/T30-1)*100) | V30: =AVERAGE((L30/E30)^2,(L30/H30)^2) | W30: =IF(ABS(E30-汇总!B25)<=ABS(H30-汇总!B25),E30,H30) | X30: =(K30/W30)^2 | Y30: =IF(N30>10,"HIGH_TVW_CV",IF(J30<3,"SHORT_INTERFACE","PASS")) | Z30: Di1、TVW均值、Di2均来自本Pair_ID；TVW=3–5法线平均 | AA30: 样品45
A31: 46(1)-P01 | B31: 46 (1).tif | C31: 46(1)-V02 | D31: =导管母表_860!F162 | E31: =导管母表_860!G162 | F31: 46(1)-V03 | G31: =导管母表_860!F163 | H31: =导管母表_860!G163 | I31: J48:J48 | J31: =COUNT(TVW线测量明细!J48:J48) | K31: =AVERAGE(TVW线测量明细!J48:J48) | L31: =MEDIAN(TVW线测量明细!J48:J48) | M31: =IF(J31>1,STDEV(TVW线测量明细!J48:J48),0) | N31: =IF(K31=0,"",M31/K31*100) | O31: 6.0284455 | P31: =IF(O31=0,"",(K31/O31-1)*100) | Q31: =(K31/E31)^2 | R31: =(K31/H31)^2 | S31: =AVERAGE(Q31,R31) | T31: =AVERAGE((O31/E31)^2,(O31/H31)^2) | U31: =IF(T31=0,"",(S31/T31-1)*100) | V31: =AVERAGE((L31/E31)^2,(L31/H31)^2) | W31: =IF(ABS(E31-汇总!B25)<=ABS(H31-汇总!B25),E31,H31) | X31: =(K31/W31)^2 | Y31: =IF(N31>10,"HIGH_TVW_CV",IF(J31<3,"SHORT_INTERFACE","PASS")) | Z31: Di1、TVW均值、Di2均来自本Pair_ID；TVW=3–5法线平均 | AA31: 样品46
A32: 46(3)-P01 | B32: 46 (3).tif | C32: 46(3)-V01 | D32: =导管母表_860!F168 | E32: =导管母表_860!G168 | F32: 46(3)-V02 | G32: =导管母表_860!F169 | H32: =导管母表_860!G169 | I32: J49:J49 | J32: =COUNT(TVW线测量明细!J49:J49) | K32: =AVERAGE(TVW线测量明细!J49:J49) | L32: =MEDIAN(TVW线测量明细!J49:J49) | M32: =IF(J32>1,STDEV(TVW线测量明细!J49:J49),0) | N32: =IF(K32=0,"",M32/K32*100) | O32: 2.341376 | P32: =IF(O32=0,"",(K32/O32-1)*100) | Q32: =(K32/E32)^2 | R32: =(K32/H32)^2 | S32: =AVERAGE(Q32,R32) | T32: =AVERAGE((O32/E32)^2,(O32/H32)^2) | U32: =IF(T32=0,"",(S32/T32-1)*100) | V32: =AVERAGE((L32/E32)^2,(L32/H32)^2) | W32: =IF(ABS(E32-汇总!B25)<=ABS(H32-汇总!B25),E32,H32) | X32: =(K32/W32)^2 | Y32: =IF(N32>10,"HIGH_TVW_CV",IF(J32<3,"SHORT_INTERFACE","PASS")) | Z32: Di1、TVW均值、Di2均来自本Pair_ID；TVW=3–5法线平均 | AA32: 样品46
A33: 46(5)-P01 | B33: 46 (5).tif | C33: 46(5)-V02 | D33: =导管母表_860!F175 | E33: =导管母表_860!G175 | F33: 46(5)-V06 | G33: =导管母表_860!F179 | H33: =导管母表_860!G179 | I33: J50:J52 | J33: =COUNT(TVW线测量明细!J50:J52) | K33: =AVERAGE(TVW线测量明细!J50:J52) | L33: =MEDIAN(TVW线测量明细!J50:J52) | M33: =IF(J33>1,STDEV(TVW线测量明细!J50:J52),0) | N33: =IF(K33=0,"",M33/K33*100) | O33: 5.070393 | P33: =IF(O33=0,"",(K33/O33-1)*100) | Q33: =(K33/E33)^2 | R33: =(K33/H33)^2 | S33: =AVERAGE(Q33,R33) | T33: =AVERAGE((O33/E33)^2,(O33/H33)^2) | U33: =IF(T33=0,"",(S33/T33-1)*100) | V33: =AVERAGE((L33/E33)^2,(L33/H33)^2) | W33: =IF(ABS(E33-汇总!B25)<=ABS(H33-汇总!B25),E33,H33) | X33: =(K33/W33)^2 | Y33: =IF(N33>10,"HIGH_TVW_CV",IF(J33<3,"SHORT_INTERFACE","PASS")) | Z33: Di1、TVW均值、Di2均来自本Pair_ID；TVW=3–5法线平均 | AA33: 样品46
A34: 46(7)-P01 | B34: 46 (7).tif | C34: 46(7)-V01 | D34: =导管母表_860!F183 | E34: =导管母表_860!G183 | F34: 46(7)-V02 | G34: =导管母表_860!F184 | H34: =导管母表_860!G184 | I34: J53:J56 | J34: =COUNT(TVW线测量明细!J53:J56) | K34: =AVERAGE(TVW线测量明细!J53:J56) | L34: =MEDIAN(TVW线测量明细!J53:J56) | M34: =IF(J34>1,STDEV(TVW线测量明细!J53:J56),0) | N34: =IF(K34=0,"",M34/K34*100) | O34: 3.8888139 | P34: =IF(O34=0,"",(K34/O34-1)*100) | Q34: =(K34/E34)^2 | R34: =(K34/H34)^2 | S34: =AVERAGE(Q34,R34) | T34: =AVERAGE((O34/E34)^2,(O34/H34)^2) | U34: =IF(T34=0,"",(S34/T34-1)*100) | V34: =AVERAGE((L34/E34)^2,(L34/H34)^2) | W34: =IF(ABS(E34-汇总!B25)<=ABS(H34-汇总!B25),E34,H34) | X34: =(K34/W34)^2 | Y34: =IF(N34>10,"HIGH_TVW_CV",IF(J34<3,"SHORT_INTERFACE","PASS")) | Z34: Di1、TVW均值、Di2均来自本Pair_ID；TVW=3–5法线平均 | AA34: 样品46
A35: 47(1)-P01 | B35: 47 (1).tif | C35: 47(1)-V03 | D35: =导管母表_860!F193 | E35: =导管母表_860!G193 | F35: 47(1)-V05 | G35: =导管母表_860!F195 | H35: =导管母表_860!G195 | I35: J57:J58 | J35: =COUNT(TVW线测量明细!J57:J58) | K35: =AVERAGE(TVW线测量明细!J57:J58) | L35: =MEDIAN(TVW线测量明细!J57:J58) | M35: =IF(J35>1,STDEV(TVW线测量明细!J57:J58),0) | N35: =IF(K35=0,"",M35/K35*100) | O35: 11.27295 | P35: =IF(O35=0,"",(K35/O35-1)*100) | Q35: =(K35/E35)^2 | R35: =(K35/H35)^2 | S35: =AVERAGE(Q35,R35) | T35: =AVERAGE((O35/E35)^2,(O35/H35)^2) | U35: =IF(T35=0,"",(S35/T35-1)*100) | V35: =AVERAGE((L35/E35)^2,(L35/H35)^2) | W35: =IF(ABS(E35-汇总!B25)<=ABS(H35-汇总!B25),E35,H35) | X35: =(K35/W35)^2 | Y35: =IF(N35>10,"HIGH_TVW_CV",IF(J35<3,"SHORT_INTERFACE","PASS")) | Z35: Di1、TVW均值、Di2均来自本Pair_ID；TVW=3–5法线平均 | AA35: 样品47
A36: 47(3)-P01 | B36: 47 (3).tif | C36: 47(3)-V04 | D36: =导管母表_860!F204 | E36: =导管母表_860!G204 | F36: 47(3)-V05 | G36: =导管母表_860!F205 | H36: =导管母表_860!G205 | I36: J59:J61 | J36: =COUNT(TVW线测量明细!J59:J61) | K36: =AVERAGE(TVW线测量明细!J59:J61) | L36: =MEDIAN(TVW线测量明细!J59:J61) | M36: =IF(J36>1,STDEV(TVW线测量明细!J59:J61),0) | N36: =IF(K36=0,"",M36/K36*100) | O36: 5.2354759 | P36: =IF(O36=0,"",(K36/O36-1)*100) | Q36: =(K36/E36)^2 | R36: =(K36/H36)^2 | S36: =AVERAGE(Q36,R36) | T36: =AVERAGE((O36/E36)^2,(O36/H36)^2) | U36: =IF(T36=0,"",(S36/T36-1)*100) | V36: =AVERAGE((L36/E36)^2,(L36/H36)^2) | W36: =IF(ABS(E36-汇总!B25)<=ABS(H36-汇总!B25),E36,H36) | X36: =(K36/W36)^2 | Y36: =IF(N36>10,"HIGH_TVW_CV",IF(J36<3,"SHORT_INTERFACE","PASS")) | Z36: Di1、TVW均值、Di2均来自本Pair_ID；TVW=3–5法线平均 | AA36: 样品47
A37: 47(5)-P01 | B37: 47 (5).tif | C37: 47(5)-V03 | D37: =导管母表_860!F213 | E37: =导管母表_860!G213 | F37: 47(5)-V04 | G37: =导管母表_860!F214 | H37: =导管母表_860!G214 | I37: J62:J62 | J37: =COUNT(TVW线测量明细!J62:J62) | K37: =AVERAGE(TVW线测量明细!J62:J62) | L37: =MEDIAN(TVW线测量明细!J62:J62) | M37: =IF(J37>1,STDEV(TVW线测量明细!J62:J62),0) | N37: =IF(K37=0,"",M37/K37*100) | O37: 0 | P37: =IF(O37=0,"",(K37/O37-1)*100) | Q37: =(K37/E37)^2 | R37: =(K37/H37)^2 | S37: =AVERAGE(Q37,R37) | T37: =AVERAGE((O37/E37)^2,(O37/H37)^2) | U37: =IF(T37=0,"",(S37/T37-1)*100) | V37: =AVERAGE((L37/E37)^2,(L37/H37)^2) | W37: =IF(ABS(E37-汇总!B25)<=ABS(H37-汇总!B25),E37,H37) | X37: =(K37/W37)^2 | Y37: =IF(N37>10,"HIGH_TVW_CV",IF(J37<3,"SHORT_INTERFACE","PASS")) | Z37: Di1、TVW均值、Di2均来自本Pair_ID；TVW=3–5法线平均 | AA37: 样品47
